(0.002) 
            SELECT c.relname,
            CASE WHEN c.relispartition THEN 'p' WHEN c.relkind IN ('m', 'v') THEN 'v' ELSE 't' END
            FROM pg_catalog.pg_class c
            LEFT JOIN pg_catalog.pg_namespace n ON n.oid = c.relnamespace
            WHERE c.relkind IN ('f', 'm', 'p', 'r', 'v')
                AND n.nspname NOT IN ('pg_catalog', 'pg_toast')
                AND pg_catalog.pg_table_is_visible(c.oid)
        ; args=None; alias=default
(0.000) SELECT "django_migrations"."id", "django_migrations"."app", "django_migrations"."name", "django_migrations"."applied" FROM "django_migrations"; args=(); alias=default
(0.001) 
            SELECT c.relname,
            CASE WHEN c.relispartition THEN 'p' WHEN c.relkind IN ('m', 'v') THEN 'v' ELSE 't' END
            FROM pg_catalog.pg_class c
            LEFT JOIN pg_catalog.pg_namespace n ON n.oid = c.relnamespace
            WHERE c.relkind IN ('f', 'm', 'p', 'r', 'v')
                AND n.nspname NOT IN ('pg_catalog', 'pg_toast')
                AND pg_catalog.pg_table_is_visible(c.oid)
        ; args=None; alias=default
(0.000) SELECT "django_migrations"."id", "django_migrations"."app", "django_migrations"."name", "django_migrations"."applied" FROM "django_migrations"; args=(); alias=default
(0.000) 
            SELECT c.relname,
            CASE WHEN c.relispartition THEN 'p' WHEN c.relkind IN ('m', 'v') THEN 'v' ELSE 't' END
            FROM pg_catalog.pg_class c
            LEFT JOIN pg_catalog.pg_namespace n ON n.oid = c.relnamespace
            WHERE c.relkind IN ('f', 'm', 'p', 'r', 'v')
                AND n.nspname NOT IN ('pg_catalog', 'pg_toast')
                AND pg_catalog.pg_table_is_visible(c.oid)
        ; args=None; alias=default
(0.000) SELECT "django_migrations"."id", "django_migrations"."app", "django_migrations"."name", "django_migrations"."applied" FROM "django_migrations"; args=(); alias=default
(0.001) 
            SELECT c.relname,
            CASE WHEN c.relispartition THEN 'p' WHEN c.relkind IN ('m', 'v') THEN 'v' ELSE 't' END
            FROM pg_catalog.pg_class c
            LEFT JOIN pg_catalog.pg_namespace n ON n.oid = c.relnamespace
            WHERE c.relkind IN ('f', 'm', 'p', 'r', 'v')
                AND n.nspname NOT IN ('pg_catalog', 'pg_toast')
                AND pg_catalog.pg_table_is_visible(c.oid)
        ; args=None; alias=default
(0.001) 
            SELECT c.relname,
            CASE WHEN c.relispartition THEN 'p' WHEN c.relkind IN ('m', 'v') THEN 'v' ELSE 't' END
            FROM pg_catalog.pg_class c
            LEFT JOIN pg_catalog.pg_namespace n ON n.oid = c.relnamespace
            WHERE c.relkind IN ('f', 'm', 'p', 'r', 'v')
                AND n.nspname NOT IN ('pg_catalog', 'pg_toast')
                AND pg_catalog.pg_table_is_visible(c.oid)
        ; args=None; alias=default
(0.000) SELECT "django_migrations"."id", "django_migrations"."app", "django_migrations"."name", "django_migrations"."applied" FROM "django_migrations"; args=(); alias=default
(0.001) SELECT "django_content_type"."id", "django_content_type"."app_label", "django_content_type"."model" FROM "django_content_type" WHERE "django_content_type"."app_label" = 'admin'; args=('admin',); alias=default
(0.017) SELECT "django_content_type"."id", "django_content_type"."app_label", "django_content_type"."model" FROM "django_content_type" WHERE ("django_content_type"."app_label" = 'admin' AND "django_content_type"."model" = 'logentry') LIMIT 21; args=('admin', 'logentry'); alias=default
(0.001) SELECT "auth_permission"."content_type_id", "auth_permission"."codename" FROM "auth_permission" INNER JOIN "django_content_type" ON ("auth_permission"."content_type_id" = "django_content_type"."id") WHERE "auth_permission"."content_type_id" IN (1) ORDER BY "django_content_type"."app_label" ASC, "django_content_type"."model" ASC, "auth_permission"."codename" ASC; args=(1,); alias=default
(0.000) SELECT "django_content_type"."id", "django_content_type"."app_label", "django_content_type"."model" FROM "django_content_type" WHERE "django_content_type"."app_label" = 'admin'; args=('admin',); alias=default
(0.000) SELECT "django_content_type"."id", "django_content_type"."app_label", "django_content_type"."model" FROM "django_content_type" WHERE "django_content_type"."app_label" = 'auth'; args=('auth',); alias=default
(0.000) SELECT "django_content_type"."id", "django_content_type"."app_label", "django_content_type"."model" FROM "django_content_type" WHERE ("django_content_type"."app_label" = 'auth' AND "django_content_type"."model" = 'permission') LIMIT 21; args=('auth', 'permission'); alias=default
(0.000) SELECT "django_content_type"."id", "django_content_type"."app_label", "django_content_type"."model" FROM "django_content_type" WHERE ("django_content_type"."app_label" = 'auth' AND "django_content_type"."model" = 'group') LIMIT 21; args=('auth', 'group'); alias=default
(0.000) SELECT "auth_permission"."content_type_id", "auth_permission"."codename" FROM "auth_permission" INNER JOIN "django_content_type" ON ("auth_permission"."content_type_id" = "django_content_type"."id") WHERE "auth_permission"."content_type_id" IN (2, 3) ORDER BY "django_content_type"."app_label" ASC, "django_content_type"."model" ASC, "auth_permission"."codename" ASC; args=(2, 3); alias=default
(0.000) SELECT "django_content_type"."id", "django_content_type"."app_label", "django_content_type"."model" FROM "django_content_type" WHERE "django_content_type"."app_label" = 'auth'; args=('auth',); alias=default
(0.001) SELECT "django_content_type"."id", "django_content_type"."app_label", "django_content_type"."model" FROM "django_content_type" WHERE "django_content_type"."app_label" = 'contenttypes'; args=('contenttypes',); alias=default
(0.000) SELECT "django_content_type"."id", "django_content_type"."app_label", "django_content_type"."model" FROM "django_content_type" WHERE ("django_content_type"."app_label" = 'contenttypes' AND "django_content_type"."model" = 'contenttype') LIMIT 21; args=('contenttypes', 'contenttype'); alias=default
(0.000) SELECT "auth_permission"."content_type_id", "auth_permission"."codename" FROM "auth_permission" INNER JOIN "django_content_type" ON ("auth_permission"."content_type_id" = "django_content_type"."id") WHERE "auth_permission"."content_type_id" IN (4) ORDER BY "django_content_type"."app_label" ASC, "django_content_type"."model" ASC, "auth_permission"."codename" ASC; args=(4,); alias=default
(0.000) SELECT "django_content_type"."id", "django_content_type"."app_label", "django_content_type"."model" FROM "django_content_type" WHERE "django_content_type"."app_label" = 'contenttypes'; args=('contenttypes',); alias=default
(0.000) SELECT "django_content_type"."id", "django_content_type"."app_label", "django_content_type"."model" FROM "django_content_type" WHERE "django_content_type"."app_label" = 'sessions'; args=('sessions',); alias=default
(0.000) SELECT "django_content_type"."id", "django_content_type"."app_label", "django_content_type"."model" FROM "django_content_type" WHERE ("django_content_type"."app_label" = 'sessions' AND "django_content_type"."model" = 'session') LIMIT 21; args=('sessions', 'session'); alias=default
(0.000) SELECT "auth_permission"."content_type_id", "auth_permission"."codename" FROM "auth_permission" INNER JOIN "django_content_type" ON ("auth_permission"."content_type_id" = "django_content_type"."id") WHERE "auth_permission"."content_type_id" IN (5) ORDER BY "django_content_type"."app_label" ASC, "django_content_type"."model" ASC, "auth_permission"."codename" ASC; args=(5,); alias=default
(0.000) SELECT "django_content_type"."id", "django_content_type"."app_label", "django_content_type"."model" FROM "django_content_type" WHERE "django_content_type"."app_label" = 'sessions'; args=('sessions',); alias=default
(0.000) SELECT "django_content_type"."id", "django_content_type"."app_label", "django_content_type"."model" FROM "django_content_type" WHERE "django_content_type"."app_label" = 'core'; args=('core',); alias=default
(0.000) SELECT "django_content_type"."id", "django_content_type"."app_label", "django_content_type"."model" FROM "django_content_type" WHERE ("django_content_type"."app_label" = 'core' AND "django_content_type"."model" = 'country') LIMIT 21; args=('core', 'country'); alias=default
(0.000) SELECT "django_content_type"."id", "django_content_type"."app_label", "django_content_type"."model" FROM "django_content_type" WHERE ("django_content_type"."app_label" = 'core' AND "django_content_type"."model" = 'customuser') LIMIT 21; args=('core', 'customuser'); alias=default
(0.000) SELECT "auth_permission"."content_type_id", "auth_permission"."codename" FROM "auth_permission" INNER JOIN "django_content_type" ON ("auth_permission"."content_type_id" = "django_content_type"."id") WHERE "auth_permission"."content_type_id" IN (6, 7) ORDER BY "django_content_type"."app_label" ASC, "django_content_type"."model" ASC, "auth_permission"."codename" ASC; args=(6, 7); alias=default
(0.000) SELECT "django_content_type"."id", "django_content_type"."app_label", "django_content_type"."model" FROM "django_content_type" WHERE "django_content_type"."app_label" = 'core'; args=('core',); alias=default
(0.003) SELECT "django_session"."session_key", "django_session"."session_data", "django_session"."expire_date" FROM "django_session" WHERE ("django_session"."expire_date" > '2025-03-25T16:08:39.226290+00:00'::timestamptz AND "django_session"."session_key" = 'ekfvdgjqowzfv5gb4m6zaduzjn9jsb1m') LIMIT 21; args=(datetime.datetime(2025, 3, 25, 16, 8, 39, 226290, tzinfo=datetime.timezone.utc), 'ekfvdgjqowzfv5gb4m6zaduzjn9jsb1m'); alias=default
Exception while resolving variable 'login_form' in template 'index.html'.
Traceback (most recent call last):
  File "/usr/local/lib/python3.9/site-packages/django/template/base.py", line 862, in _resolve_lookup
    current = current[bit]
  File "/usr/local/lib/python3.9/site-packages/django/template/context.py", line 83, in __getitem__
    raise KeyError(key)
KeyError: 'login_form'

During handling of the above exception, another exception occurred:

Traceback (most recent call last):
  File "/usr/local/lib/python3.9/site-packages/django/template/base.py", line 868, in _resolve_lookup
    if isinstance(current, BaseContext) and getattr(type(current), bit):
AttributeError: type object 'RequestContext' has no attribute 'login_form'

During handling of the above exception, another exception occurred:

Traceback (most recent call last):
  File "/usr/local/lib/python3.9/site-packages/django/template/base.py", line 876, in _resolve_lookup
    current = current[int(bit)]
ValueError: invalid literal for int() with base 10: 'login_form'

During handling of the above exception, another exception occurred:

Traceback (most recent call last):
  File "/usr/local/lib/python3.9/site-packages/django/template/base.py", line 881, in _resolve_lookup
    raise VariableDoesNotExist("Failed lookup for key "
django.template.base.VariableDoesNotExist: Failed lookup for key [login_form] in [{'True': True, 'False': False, 'None': None}, {'csrf_token': <SimpleLazyObject: <function csrf.<locals>._get_val at 0x7fbda2d4d9d0>>, 'request': <WSGIRequest: GET '/'>, 'user': <SimpleLazyObject: <django.contrib.auth.models.AnonymousUser object at 0x7fbda2d96f70>>, 'perms': PermWrapper(<SimpleLazyObject: <django.contrib.auth.models.AnonymousUser object at 0x7fbda2d96f70>>), 'messages': <FallbackStorage: request=<WSGIRequest: GET '/'>>, 'DEFAULT_MESSAGE_LEVELS': {'DEBUG': 10, 'INFO': 20, 'SUCCESS': 25, 'WARNING': 30, 'ERROR': 40}}, {}, {}, {}]
Exception while resolving variable 'reg_form' in template 'index.html'.
Traceback (most recent call last):
  File "/usr/local/lib/python3.9/site-packages/django/template/base.py", line 862, in _resolve_lookup
    current = current[bit]
  File "/usr/local/lib/python3.9/site-packages/django/template/context.py", line 83, in __getitem__
    raise KeyError(key)
KeyError: 'reg_form'

During handling of the above exception, another exception occurred:

Traceback (most recent call last):
  File "/usr/local/lib/python3.9/site-packages/django/template/base.py", line 868, in _resolve_lookup
    if isinstance(current, BaseContext) and getattr(type(current), bit):
AttributeError: type object 'RequestContext' has no attribute 'reg_form'

During handling of the above exception, another exception occurred:

Traceback (most recent call last):
  File "/usr/local/lib/python3.9/site-packages/django/template/base.py", line 876, in _resolve_lookup
    current = current[int(bit)]
ValueError: invalid literal for int() with base 10: 'reg_form'

During handling of the above exception, another exception occurred:

Traceback (most recent call last):
  File "/usr/local/lib/python3.9/site-packages/django/template/base.py", line 881, in _resolve_lookup
    raise VariableDoesNotExist("Failed lookup for key "
django.template.base.VariableDoesNotExist: Failed lookup for key [reg_form] in [{'True': True, 'False': False, 'None': None}, {'csrf_token': <SimpleLazyObject: 'Ek8h0pzxYjPOiQ5iOuHdooch0Im9rRxzIeHWqblgh1okoidw4ScGphumCFBYfKMx'>, 'request': <WSGIRequest: GET '/'>, 'user': <SimpleLazyObject: <django.contrib.auth.models.AnonymousUser object at 0x7fbda2d96f70>>, 'perms': PermWrapper(<SimpleLazyObject: <django.contrib.auth.models.AnonymousUser object at 0x7fbda2d96f70>>), 'messages': <FallbackStorage: request=<WSGIRequest: GET '/'>>, 'DEFAULT_MESSAGE_LEVELS': {'DEBUG': 10, 'INFO': 20, 'SUCCESS': 25, 'WARNING': 30, 'ERROR': 40}}, {}, {}, {}]
Exception while resolving variable 'destination' in template 'index.html'.
Traceback (most recent call last):
  File "/usr/local/lib/python3.9/site-packages/django/utils/datastructures.py", line 83, in __getitem__
    list_ = super().__getitem__(key)
KeyError: 'destination'

During handling of the above exception, another exception occurred:

Traceback (most recent call last):
  File "/usr/local/lib/python3.9/site-packages/django/template/base.py", line 862, in _resolve_lookup
    current = current[bit]
  File "/usr/local/lib/python3.9/site-packages/django/utils/datastructures.py", line 85, in __getitem__
    raise MultiValueDictKeyError(key)
django.utils.datastructures.MultiValueDictKeyError: 'destination'

During handling of the above exception, another exception occurred:

Traceback (most recent call last):
  File "/usr/local/lib/python3.9/site-packages/django/template/base.py", line 870, in _resolve_lookup
    current = getattr(current, bit)
AttributeError: 'QueryDict' object has no attribute 'destination'

During handling of the above exception, another exception occurred:

Traceback (most recent call last):
  File "/usr/local/lib/python3.9/site-packages/django/template/base.py", line 876, in _resolve_lookup
    current = current[int(bit)]
ValueError: invalid literal for int() with base 10: 'destination'

During handling of the above exception, another exception occurred:

Traceback (most recent call last):
  File "/usr/local/lib/python3.9/site-packages/django/template/base.py", line 881, in _resolve_lookup
    raise VariableDoesNotExist("Failed lookup for key "
django.template.base.VariableDoesNotExist: Failed lookup for key [destination] in <QueryDict: {}>
Exception while resolving variable 'people' in template 'index.html'.
Traceback (most recent call last):
  File "/usr/local/lib/python3.9/site-packages/django/utils/datastructures.py", line 83, in __getitem__
    list_ = super().__getitem__(key)
KeyError: 'people'

During handling of the above exception, another exception occurred:

Traceback (most recent call last):
  File "/usr/local/lib/python3.9/site-packages/django/template/base.py", line 862, in _resolve_lookup
    current = current[bit]
  File "/usr/local/lib/python3.9/site-packages/django/utils/datastructures.py", line 85, in __getitem__
    raise MultiValueDictKeyError(key)
django.utils.datastructures.MultiValueDictKeyError: 'people'

During handling of the above exception, another exception occurred:

Traceback (most recent call last):
  File "/usr/local/lib/python3.9/site-packages/django/template/base.py", line 870, in _resolve_lookup
    current = getattr(current, bit)
AttributeError: 'QueryDict' object has no attribute 'people'

During handling of the above exception, another exception occurred:

Traceback (most recent call last):
  File "/usr/local/lib/python3.9/site-packages/django/template/base.py", line 876, in _resolve_lookup
    current = current[int(bit)]
ValueError: invalid literal for int() with base 10: 'people'

During handling of the above exception, another exception occurred:

Traceback (most recent call last):
  File "/usr/local/lib/python3.9/site-packages/django/template/base.py", line 881, in _resolve_lookup
    raise VariableDoesNotExist("Failed lookup for key "
django.template.base.VariableDoesNotExist: Failed lookup for key [people] in <QueryDict: {}>
Exception while resolving variable 'days' in template 'index.html'.
Traceback (most recent call last):
  File "/usr/local/lib/python3.9/site-packages/django/utils/datastructures.py", line 83, in __getitem__
    list_ = super().__getitem__(key)
KeyError: 'days'

During handling of the above exception, another exception occurred:

Traceback (most recent call last):
  File "/usr/local/lib/python3.9/site-packages/django/template/base.py", line 862, in _resolve_lookup
    current = current[bit]
  File "/usr/local/lib/python3.9/site-packages/django/utils/datastructures.py", line 85, in __getitem__
    raise MultiValueDictKeyError(key)
django.utils.datastructures.MultiValueDictKeyError: 'days'

During handling of the above exception, another exception occurred:

Traceback (most recent call last):
  File "/usr/local/lib/python3.9/site-packages/django/template/base.py", line 870, in _resolve_lookup
    current = getattr(current, bit)
AttributeError: 'QueryDict' object has no attribute 'days'

During handling of the above exception, another exception occurred:

Traceback (most recent call last):
  File "/usr/local/lib/python3.9/site-packages/django/template/base.py", line 876, in _resolve_lookup
    current = current[int(bit)]
ValueError: invalid literal for int() with base 10: 'days'

During handling of the above exception, another exception occurred:

Traceback (most recent call last):
  File "/usr/local/lib/python3.9/site-packages/django/template/base.py", line 881, in _resolve_lookup
    raise VariableDoesNotExist("Failed lookup for key "
django.template.base.VariableDoesNotExist: Failed lookup for key [days] in <QueryDict: {}>
Exception while resolving variable 'get_error_message' in template 'index.html'.
Traceback (most recent call last):
  File "/usr/local/lib/python3.9/site-packages/django/template/base.py", line 862, in _resolve_lookup
    current = current[bit]
TypeError: 'FallbackStorage' object is not subscriptable

During handling of the above exception, another exception occurred:

Traceback (most recent call last):
  File "/usr/local/lib/python3.9/site-packages/django/template/base.py", line 870, in _resolve_lookup
    current = getattr(current, bit)
AttributeError: 'FallbackStorage' object has no attribute 'get_error_message'

During handling of the above exception, another exception occurred:

Traceback (most recent call last):
  File "/usr/local/lib/python3.9/site-packages/django/template/base.py", line 876, in _resolve_lookup
    current = current[int(bit)]
ValueError: invalid literal for int() with base 10: 'get_error_message'

During handling of the above exception, another exception occurred:

Traceback (most recent call last):
  File "/usr/local/lib/python3.9/site-packages/django/template/base.py", line 881, in _resolve_lookup
    raise VariableDoesNotExist("Failed lookup for key "
django.template.base.VariableDoesNotExist: Failed lookup for key [get_error_message] in <FallbackStorage: request=<WSGIRequest: GET '/'>>
Exception while resolving variable 'searched' in template 'index.html'.
Traceback (most recent call last):
  File "/usr/local/lib/python3.9/site-packages/django/template/base.py", line 862, in _resolve_lookup
    current = current[bit]
  File "/usr/local/lib/python3.9/site-packages/django/template/context.py", line 83, in __getitem__
    raise KeyError(key)
KeyError: 'searched'

During handling of the above exception, another exception occurred:

Traceback (most recent call last):
  File "/usr/local/lib/python3.9/site-packages/django/template/base.py", line 868, in _resolve_lookup
    if isinstance(current, BaseContext) and getattr(type(current), bit):
AttributeError: type object 'RequestContext' has no attribute 'searched'

During handling of the above exception, another exception occurred:

Traceback (most recent call last):
  File "/usr/local/lib/python3.9/site-packages/django/template/base.py", line 876, in _resolve_lookup
    current = current[int(bit)]
ValueError: invalid literal for int() with base 10: 'searched'

During handling of the above exception, another exception occurred:

Traceback (most recent call last):
  File "/usr/local/lib/python3.9/site-packages/django/template/base.py", line 881, in _resolve_lookup
    raise VariableDoesNotExist("Failed lookup for key "
django.template.base.VariableDoesNotExist: Failed lookup for key [searched] in [{'True': True, 'False': False, 'None': None}, {'csrf_token': <SimpleLazyObject: 'Ek8h0pzxYjPOiQ5iOuHdooch0Im9rRxzIeHWqblgh1okoidw4ScGphumCFBYfKMx'>, 'request': <WSGIRequest: GET '/'>, 'user': <SimpleLazyObject: <django.contrib.auth.models.AnonymousUser object at 0x7fbda2d96f70>>, 'perms': PermWrapper(<SimpleLazyObject: <django.contrib.auth.models.AnonymousUser object at 0x7fbda2d96f70>>), 'messages': <FallbackStorage: request=<WSGIRequest: GET '/'>>, 'DEFAULT_MESSAGE_LEVELS': {'DEBUG': 10, 'INFO': 20, 'SUCCESS': 25, 'WARNING': 30, 'ERROR': 40}}, {}, {}]
"GET / HTTP/1.1" 200 19634
"GET /static/css/loginregister.css HTTP/1.1" 200 1611
"GET /static/images/logo.svg HTTP/1.1" 200 4219
"GET /static/images/logo-blue.svg HTTP/1.1" 200 4227
"GET /static/css/style.css HTTP/1.1" 200 19709
"GET /static/css/search.css HTTP/1.1" 200 4914
"GET /static/images/gallery-2.jpg HTTP/1.1" 200 27553
"GET /static/js/loginregister.js HTTP/1.1" 200 1092
"GET /static/images/gallery-1.jpg HTTP/1.1" 200 73873
"GET /static/images/popular-1.jpg HTTP/1.1" 200 69929
"GET /static/js/script.js HTTP/1.1" 200 1105
"GET /static/images/gallery-4.jpg HTTP/1.1" 200 36651
"GET /static/images/gallery-3.jpg HTTP/1.1" 200 86138
"GET /static/images/gallery-5.jpg HTTP/1.1" 200 48045
"GET /static/images/popular-2.jpg HTTP/1.1" 200 68322
"GET /static/images/popular-3.jpg HTTP/1.1" 200 95631
File /usr/local/lib/python3.9/site-packages/django/contrib/messages/storage/base.py first seen with mtime 1742333652.0
"GET /static/images/hero-banner.jpg HTTP/1.1" 200 341002
File /usr/local/lib/python3.9/site-packages/django/contrib/staticfiles/storage.py first seen with mtime 1742333652.0
File /usr/local/lib/python3.9/site-packages/django/contrib/messages/storage/session.py first seen with mtime 1742333652.0
File /usr/local/lib/python3.9/site-packages/django/contrib/messages/context_processors.py first seen with mtime 1742333652.0
File /usr/local/lib/python3.9/site-packages/django/contrib/messages/storage/fallback.py first seen with mtime 1742333652.0
File /usr/local/lib/python3.9/site-packages/django/contrib/sessions/serializers.py first seen with mtime 1742333652.0
File /usr/local/lib/python3.9/site-packages/django/contrib/auth/context_processors.py first seen with mtime 1742333651.0
File /usr/local/lib/python3.9/site-packages/django/contrib/messages/storage/cookie.py first seen with mtime 1742333652.0
File /usr/local/lib/python3.9/site-packages/django/template/context_processors.py first seen with mtime 1742333652.0
File /usr/local/lib/python3.9/site-packages/django/contrib/messages/utils.py first seen with mtime 1742333652.0
Not Found: /assets/images/favicon.svg
"GET /assets/images/favicon.svg HTTP/1.1" 404 3373
(0.001) SELECT "core_customuser"."id", "core_customuser"."password", "core_customuser"."last_login", "core_customuser"."is_superuser", "core_customuser"."username", "core_customuser"."first_name", "core_customuser"."last_name", "core_customuser"."email", "core_customuser"."is_staff", "core_customuser"."is_active", "core_customuser"."date_joined", "core_customuser"."country_id", "core_customuser"."budget", "core_customuser"."currency" FROM "core_customuser" WHERE "core_customuser"."username" = 'TP000000' LIMIT 21; args=('TP000000',); alias=default
Exception while resolving variable 'login_form' in template 'index.html'.
Traceback (most recent call last):
  File "/usr/local/lib/python3.9/site-packages/django/template/base.py", line 862, in _resolve_lookup
    current = current[bit]
  File "/usr/local/lib/python3.9/site-packages/django/template/context.py", line 83, in __getitem__
    raise KeyError(key)
KeyError: 'login_form'

During handling of the above exception, another exception occurred:

Traceback (most recent call last):
  File "/usr/local/lib/python3.9/site-packages/django/template/base.py", line 868, in _resolve_lookup
    if isinstance(current, BaseContext) and getattr(type(current), bit):
AttributeError: type object 'RequestContext' has no attribute 'login_form'

During handling of the above exception, another exception occurred:

Traceback (most recent call last):
  File "/usr/local/lib/python3.9/site-packages/django/template/base.py", line 876, in _resolve_lookup
    current = current[int(bit)]
ValueError: invalid literal for int() with base 10: 'login_form'

During handling of the above exception, another exception occurred:

Traceback (most recent call last):
  File "/usr/local/lib/python3.9/site-packages/django/template/base.py", line 881, in _resolve_lookup
    raise VariableDoesNotExist("Failed lookup for key "
django.template.base.VariableDoesNotExist: Failed lookup for key [login_form] in [{'True': True, 'False': False, 'None': None}, {'csrf_token': <SimpleLazyObject: <function csrf.<locals>._get_val at 0x7fbda01b2e50>>, 'request': <WSGIRequest: POST '/login/'>, 'user': <SimpleLazyObject: <django.contrib.auth.models.AnonymousUser object at 0x7fbda010eeb0>>, 'perms': PermWrapper(<SimpleLazyObject: <django.contrib.auth.models.AnonymousUser object at 0x7fbda010eeb0>>), 'messages': <FallbackStorage: request=<WSGIRequest: POST '/login/'>>, 'DEFAULT_MESSAGE_LEVELS': {'DEBUG': 10, 'INFO': 20, 'SUCCESS': 25, 'WARNING': 30, 'ERROR': 40}}, {}, {'form': <AuthenticationForm bound=True, valid=False, fields=(username;password)>, 'view': <django.contrib.auth.views.LoginView object at 0x7fbda2daa2e0>, 'next': '', 'site': <django.contrib.sites.requests.RequestSite object at 0x7fbda2d82df0>, 'site_name': 'localhost:8000'}, {}, {}]
Exception while resolving variable 'reg_form' in template 'index.html'.
Traceback (most recent call last):
  File "/usr/local/lib/python3.9/site-packages/django/template/base.py", line 862, in _resolve_lookup
    current = current[bit]
  File "/usr/local/lib/python3.9/site-packages/django/template/context.py", line 83, in __getitem__
    raise KeyError(key)
KeyError: 'reg_form'

During handling of the above exception, another exception occurred:

Traceback (most recent call last):
  File "/usr/local/lib/python3.9/site-packages/django/template/base.py", line 868, in _resolve_lookup
    if isinstance(current, BaseContext) and getattr(type(current), bit):
AttributeError: type object 'RequestContext' has no attribute 'reg_form'

During handling of the above exception, another exception occurred:

Traceback (most recent call last):
  File "/usr/local/lib/python3.9/site-packages/django/template/base.py", line 876, in _resolve_lookup
    current = current[int(bit)]
ValueError: invalid literal for int() with base 10: 'reg_form'

During handling of the above exception, another exception occurred:

Traceback (most recent call last):
  File "/usr/local/lib/python3.9/site-packages/django/template/base.py", line 881, in _resolve_lookup
    raise VariableDoesNotExist("Failed lookup for key "
django.template.base.VariableDoesNotExist: Failed lookup for key [reg_form] in [{'True': True, 'False': False, 'None': None}, {'csrf_token': <SimpleLazyObject: 'mR3fLpRIaMdb926we3lB1L8ePVzS9ZSwqLCUbbDrtuMHfueKurQ42EqjrSOHXS7u'>, 'request': <WSGIRequest: POST '/login/'>, 'user': <SimpleLazyObject: <django.contrib.auth.models.AnonymousUser object at 0x7fbda010eeb0>>, 'perms': PermWrapper(<SimpleLazyObject: <django.contrib.auth.models.AnonymousUser object at 0x7fbda010eeb0>>), 'messages': <FallbackStorage: request=<WSGIRequest: POST '/login/'>>, 'DEFAULT_MESSAGE_LEVELS': {'DEBUG': 10, 'INFO': 20, 'SUCCESS': 25, 'WARNING': 30, 'ERROR': 40}}, {}, {'form': <AuthenticationForm bound=True, valid=False, fields=(username;password)>, 'view': <django.contrib.auth.views.LoginView object at 0x7fbda2daa2e0>, 'next': '', 'site': <django.contrib.sites.requests.RequestSite object at 0x7fbda2d82df0>, 'site_name': 'localhost:8000'}, {}, {}]
Exception while resolving variable 'destination' in template 'index.html'.
Traceback (most recent call last):
  File "/usr/local/lib/python3.9/site-packages/django/utils/datastructures.py", line 83, in __getitem__
    list_ = super().__getitem__(key)
KeyError: 'destination'

During handling of the above exception, another exception occurred:

Traceback (most recent call last):
  File "/usr/local/lib/python3.9/site-packages/django/template/base.py", line 862, in _resolve_lookup
    current = current[bit]
  File "/usr/local/lib/python3.9/site-packages/django/utils/datastructures.py", line 85, in __getitem__
    raise MultiValueDictKeyError(key)
django.utils.datastructures.MultiValueDictKeyError: 'destination'

During handling of the above exception, another exception occurred:

Traceback (most recent call last):
  File "/usr/local/lib/python3.9/site-packages/django/template/base.py", line 870, in _resolve_lookup
    current = getattr(current, bit)
AttributeError: 'QueryDict' object has no attribute 'destination'

During handling of the above exception, another exception occurred:

Traceback (most recent call last):
  File "/usr/local/lib/python3.9/site-packages/django/template/base.py", line 876, in _resolve_lookup
    current = current[int(bit)]
ValueError: invalid literal for int() with base 10: 'destination'

During handling of the above exception, another exception occurred:

Traceback (most recent call last):
  File "/usr/local/lib/python3.9/site-packages/django/template/base.py", line 881, in _resolve_lookup
    raise VariableDoesNotExist("Failed lookup for key "
django.template.base.VariableDoesNotExist: Failed lookup for key [destination] in <QueryDict: {}>
Exception while resolving variable 'people' in template 'index.html'.
Traceback (most recent call last):
  File "/usr/local/lib/python3.9/site-packages/django/utils/datastructures.py", line 83, in __getitem__
    list_ = super().__getitem__(key)
KeyError: 'people'

During handling of the above exception, another exception occurred:

Traceback (most recent call last):
  File "/usr/local/lib/python3.9/site-packages/django/template/base.py", line 862, in _resolve_lookup
    current = current[bit]
  File "/usr/local/lib/python3.9/site-packages/django/utils/datastructures.py", line 85, in __getitem__
    raise MultiValueDictKeyError(key)
django.utils.datastructures.MultiValueDictKeyError: 'people'

During handling of the above exception, another exception occurred:

Traceback (most recent call last):
  File "/usr/local/lib/python3.9/site-packages/django/template/base.py", line 870, in _resolve_lookup
    current = getattr(current, bit)
AttributeError: 'QueryDict' object has no attribute 'people'

During handling of the above exception, another exception occurred:

Traceback (most recent call last):
  File "/usr/local/lib/python3.9/site-packages/django/template/base.py", line 876, in _resolve_lookup
    current = current[int(bit)]
ValueError: invalid literal for int() with base 10: 'people'

During handling of the above exception, another exception occurred:

Traceback (most recent call last):
  File "/usr/local/lib/python3.9/site-packages/django/template/base.py", line 881, in _resolve_lookup
    raise VariableDoesNotExist("Failed lookup for key "
django.template.base.VariableDoesNotExist: Failed lookup for key [people] in <QueryDict: {}>
Exception while resolving variable 'days' in template 'index.html'.
Traceback (most recent call last):
  File "/usr/local/lib/python3.9/site-packages/django/utils/datastructures.py", line 83, in __getitem__
    list_ = super().__getitem__(key)
KeyError: 'days'

During handling of the above exception, another exception occurred:

Traceback (most recent call last):
  File "/usr/local/lib/python3.9/site-packages/django/template/base.py", line 862, in _resolve_lookup
    current = current[bit]
  File "/usr/local/lib/python3.9/site-packages/django/utils/datastructures.py", line 85, in __getitem__
    raise MultiValueDictKeyError(key)
django.utils.datastructures.MultiValueDictKeyError: 'days'

During handling of the above exception, another exception occurred:

Traceback (most recent call last):
  File "/usr/local/lib/python3.9/site-packages/django/template/base.py", line 870, in _resolve_lookup
    current = getattr(current, bit)
AttributeError: 'QueryDict' object has no attribute 'days'

During handling of the above exception, another exception occurred:

Traceback (most recent call last):
  File "/usr/local/lib/python3.9/site-packages/django/template/base.py", line 876, in _resolve_lookup
    current = current[int(bit)]
ValueError: invalid literal for int() with base 10: 'days'

During handling of the above exception, another exception occurred:

Traceback (most recent call last):
  File "/usr/local/lib/python3.9/site-packages/django/template/base.py", line 881, in _resolve_lookup
    raise VariableDoesNotExist("Failed lookup for key "
django.template.base.VariableDoesNotExist: Failed lookup for key [days] in <QueryDict: {}>
Exception while resolving variable 'get_error_message' in template 'index.html'.
Traceback (most recent call last):
  File "/usr/local/lib/python3.9/site-packages/django/template/base.py", line 862, in _resolve_lookup
    current = current[bit]
TypeError: 'FallbackStorage' object is not subscriptable

During handling of the above exception, another exception occurred:

Traceback (most recent call last):
  File "/usr/local/lib/python3.9/site-packages/django/template/base.py", line 870, in _resolve_lookup
    current = getattr(current, bit)
AttributeError: 'FallbackStorage' object has no attribute 'get_error_message'

During handling of the above exception, another exception occurred:

Traceback (most recent call last):
  File "/usr/local/lib/python3.9/site-packages/django/template/base.py", line 876, in _resolve_lookup
    current = current[int(bit)]
ValueError: invalid literal for int() with base 10: 'get_error_message'

During handling of the above exception, another exception occurred:

Traceback (most recent call last):
  File "/usr/local/lib/python3.9/site-packages/django/template/base.py", line 881, in _resolve_lookup
    raise VariableDoesNotExist("Failed lookup for key "
django.template.base.VariableDoesNotExist: Failed lookup for key [get_error_message] in <FallbackStorage: request=<WSGIRequest: POST '/login/'>>
Exception while resolving variable 'searched' in template 'index.html'.
Traceback (most recent call last):
  File "/usr/local/lib/python3.9/site-packages/django/template/base.py", line 862, in _resolve_lookup
    current = current[bit]
  File "/usr/local/lib/python3.9/site-packages/django/template/context.py", line 83, in __getitem__
    raise KeyError(key)
KeyError: 'searched'

During handling of the above exception, another exception occurred:

Traceback (most recent call last):
  File "/usr/local/lib/python3.9/site-packages/django/template/base.py", line 868, in _resolve_lookup
    if isinstance(current, BaseContext) and getattr(type(current), bit):
AttributeError: type object 'RequestContext' has no attribute 'searched'

During handling of the above exception, another exception occurred:

Traceback (most recent call last):
  File "/usr/local/lib/python3.9/site-packages/django/template/base.py", line 876, in _resolve_lookup
    current = current[int(bit)]
ValueError: invalid literal for int() with base 10: 'searched'

During handling of the above exception, another exception occurred:

Traceback (most recent call last):
  File "/usr/local/lib/python3.9/site-packages/django/template/base.py", line 881, in _resolve_lookup
    raise VariableDoesNotExist("Failed lookup for key "
django.template.base.VariableDoesNotExist: Failed lookup for key [searched] in [{'True': True, 'False': False, 'None': None}, {'csrf_token': <SimpleLazyObject: 'mR3fLpRIaMdb926we3lB1L8ePVzS9ZSwqLCUbbDrtuMHfueKurQ42EqjrSOHXS7u'>, 'request': <WSGIRequest: POST '/login/'>, 'user': <SimpleLazyObject: <django.contrib.auth.models.AnonymousUser object at 0x7fbda010eeb0>>, 'perms': PermWrapper(<SimpleLazyObject: <django.contrib.auth.models.AnonymousUser object at 0x7fbda010eeb0>>), 'messages': <FallbackStorage: request=<WSGIRequest: POST '/login/'>>, 'DEFAULT_MESSAGE_LEVELS': {'DEBUG': 10, 'INFO': 20, 'SUCCESS': 25, 'WARNING': 30, 'ERROR': 40}}, {}, {'form': <AuthenticationForm bound=True, valid=False, fields=(username;password)>, 'view': <django.contrib.auth.views.LoginView object at 0x7fbda2daa2e0>, 'next': '', 'site': <django.contrib.sites.requests.RequestSite object at 0x7fbda2d82df0>, 'site_name': 'localhost:8000'}, {}]
"POST /login/ HTTP/1.1" 200 19634
Not Found: /serviceworker.js
"GET /serviceworker.js HTTP/1.1" 404 3346
File /usr/local/lib/python3.9/site-packages/django/contrib/sites/requests.py first seen with mtime 1742333652.0
(0.001) SELECT "core_customuser"."id", "core_customuser"."password", "core_customuser"."last_login", "core_customuser"."is_superuser", "core_customuser"."username", "core_customuser"."first_name", "core_customuser"."last_name", "core_customuser"."email", "core_customuser"."is_staff", "core_customuser"."is_active", "core_customuser"."date_joined", "core_customuser"."country_id", "core_customuser"."budget", "core_customuser"."currency" FROM "core_customuser" WHERE "core_customuser"."username" = 'user' LIMIT 21; args=('user',); alias=default
(0.001) SELECT (1) AS "a" FROM "django_session" WHERE "django_session"."session_key" = 't3u25nv8ifdkj0um0qal6s4s0zj2zawi' LIMIT 1; args=('t3u25nv8ifdkj0um0qal6s4s0zj2zawi',); alias=default
(0.001) INSERT INTO "django_session" ("session_key", "session_data", "expire_date") VALUES ('t3u25nv8ifdkj0um0qal6s4s0zj2zawi', 'e30:1tx6pZ:wv5zacPt9ihYqBHW0CFRJALXbW_vZb_6Ap_T_-KMLYE', '2025-04-08T16:08:45.436085+00:00'::timestamptz); args=('t3u25nv8ifdkj0um0qal6s4s0zj2zawi', 'e30:1tx6pZ:wv5zacPt9ihYqBHW0CFRJALXbW_vZb_6Ap_T_-KMLYE', datetime.datetime(2025, 4, 8, 16, 8, 45, 436085, tzinfo=datetime.timezone.utc)); alias=default
(0.001) UPDATE "core_customuser" SET "last_login" = '2025-03-25T16:08:45.439491+00:00'::timestamptz WHERE "core_customuser"."id" = 2; args=(datetime.datetime(2025, 3, 25, 16, 8, 45, 439491, tzinfo=datetime.timezone.utc), 2); alias=default
(0.000) UPDATE "django_session" SET "session_data" = '.eJxVjEEOwiAQRe_C2hBgEKcu3XuGZgYGqRpISrsy3l2bdKHb_977LzXSupRx7TKPU1Jn5dThd2OKD6kbSHeqt6Zjq8s8sd4UvdOury3J87K7fweFevnWdoCMxhmTAsWTZcyMwuCBcmIAFwYJACmSAwguoPWIxrPx5hiyZ1HvD9NvNzI:1tx6pZ:QrwqdhXgu9R7hLTqytxgU67f76CNtSfpTcuQOQSOjqc', "expire_date" = '2025-04-08T16:08:45.442311+00:00'::timestamptz WHERE "django_session"."session_key" = 't3u25nv8ifdkj0um0qal6s4s0zj2zawi'; args=('.eJxVjEEOwiAQRe_C2hBgEKcu3XuGZgYGqRpISrsy3l2bdKHb_977LzXSupRx7TKPU1Jn5dThd2OKD6kbSHeqt6Zjq8s8sd4UvdOury3J87K7fweFevnWdoCMxhmTAsWTZcyMwuCBcmIAFwYJACmSAwguoPWIxrPx5hiyZ1HvD9NvNzI:1tx6pZ:QrwqdhXgu9R7hLTqytxgU67f76CNtSfpTcuQOQSOjqc', datetime.datetime(2025, 4, 8, 16, 8, 45, 442311, tzinfo=datetime.timezone.utc), 't3u25nv8ifdkj0um0qal6s4s0zj2zawi'); alias=default
"POST /login/ HTTP/1.1" 302 0
(0.001) SELECT "django_session"."session_key", "django_session"."session_data", "django_session"."expire_date" FROM "django_session" WHERE ("django_session"."expire_date" > '2025-03-25T16:08:45.463943+00:00'::timestamptz AND "django_session"."session_key" = 't3u25nv8ifdkj0um0qal6s4s0zj2zawi') LIMIT 21; args=(datetime.datetime(2025, 3, 25, 16, 8, 45, 463943, tzinfo=datetime.timezone.utc), 't3u25nv8ifdkj0um0qal6s4s0zj2zawi'); alias=default
(0.001) SELECT "core_customuser"."id", "core_customuser"."password", "core_customuser"."last_login", "core_customuser"."is_superuser", "core_customuser"."username", "core_customuser"."first_name", "core_customuser"."last_name", "core_customuser"."email", "core_customuser"."is_staff", "core_customuser"."is_active", "core_customuser"."date_joined", "core_customuser"."country_id", "core_customuser"."budget", "core_customuser"."currency" FROM "core_customuser" WHERE "core_customuser"."id" = 2 LIMIT 21; args=(2,); alias=default
Exception while resolving variable 'login_form' in template 'index.html'.
Traceback (most recent call last):
  File "/usr/local/lib/python3.9/site-packages/django/template/base.py", line 862, in _resolve_lookup
    current = current[bit]
  File "/usr/local/lib/python3.9/site-packages/django/template/context.py", line 83, in __getitem__
    raise KeyError(key)
KeyError: 'login_form'

During handling of the above exception, another exception occurred:

Traceback (most recent call last):
  File "/usr/local/lib/python3.9/site-packages/django/template/base.py", line 868, in _resolve_lookup
    if isinstance(current, BaseContext) and getattr(type(current), bit):
AttributeError: type object 'RequestContext' has no attribute 'login_form'

During handling of the above exception, another exception occurred:

Traceback (most recent call last):
  File "/usr/local/lib/python3.9/site-packages/django/template/base.py", line 876, in _resolve_lookup
    current = current[int(bit)]
ValueError: invalid literal for int() with base 10: 'login_form'

During handling of the above exception, another exception occurred:

Traceback (most recent call last):
  File "/usr/local/lib/python3.9/site-packages/django/template/base.py", line 881, in _resolve_lookup
    raise VariableDoesNotExist("Failed lookup for key "
django.template.base.VariableDoesNotExist: Failed lookup for key [login_form] in [{'True': True, 'False': False, 'None': None}, {'csrf_token': <SimpleLazyObject: <function csrf.<locals>._get_val at 0x7fbda01a6ca0>>, 'request': <WSGIRequest: GET '/'>, 'user': <SimpleLazyObject: <CustomUser: user>>, 'perms': PermWrapper(<SimpleLazyObject: <CustomUser: user>>), 'messages': <FallbackStorage: request=<WSGIRequest: GET '/'>>, 'DEFAULT_MESSAGE_LEVELS': {'DEBUG': 10, 'INFO': 20, 'SUCCESS': 25, 'WARNING': 30, 'ERROR': 40}}, {}, {}, {}]
Exception while resolving variable 'reg_form' in template 'index.html'.
Traceback (most recent call last):
  File "/usr/local/lib/python3.9/site-packages/django/template/base.py", line 862, in _resolve_lookup
    current = current[bit]
  File "/usr/local/lib/python3.9/site-packages/django/template/context.py", line 83, in __getitem__
    raise KeyError(key)
KeyError: 'reg_form'

During handling of the above exception, another exception occurred:

Traceback (most recent call last):
  File "/usr/local/lib/python3.9/site-packages/django/template/base.py", line 868, in _resolve_lookup
    if isinstance(current, BaseContext) and getattr(type(current), bit):
AttributeError: type object 'RequestContext' has no attribute 'reg_form'

During handling of the above exception, another exception occurred:

Traceback (most recent call last):
  File "/usr/local/lib/python3.9/site-packages/django/template/base.py", line 876, in _resolve_lookup
    current = current[int(bit)]
ValueError: invalid literal for int() with base 10: 'reg_form'

During handling of the above exception, another exception occurred:

Traceback (most recent call last):
  File "/usr/local/lib/python3.9/site-packages/django/template/base.py", line 881, in _resolve_lookup
    raise VariableDoesNotExist("Failed lookup for key "
django.template.base.VariableDoesNotExist: Failed lookup for key [reg_form] in [{'True': True, 'False': False, 'None': None}, {'csrf_token': <SimpleLazyObject: 'cEMUT2HOcwskI7Ga8syHr09BBOL2VYIDx06xzbCp5KwZzdd77a4qizPfT4vgIvfC'>, 'request': <WSGIRequest: GET '/'>, 'user': <SimpleLazyObject: <CustomUser: user>>, 'perms': PermWrapper(<SimpleLazyObject: <CustomUser: user>>), 'messages': <FallbackStorage: request=<WSGIRequest: GET '/'>>, 'DEFAULT_MESSAGE_LEVELS': {'DEBUG': 10, 'INFO': 20, 'SUCCESS': 25, 'WARNING': 30, 'ERROR': 40}}, {}, {}, {}]
Exception while resolving variable 'destination' in template 'index.html'.
Traceback (most recent call last):
  File "/usr/local/lib/python3.9/site-packages/django/utils/datastructures.py", line 83, in __getitem__
    list_ = super().__getitem__(key)
KeyError: 'destination'

During handling of the above exception, another exception occurred:

Traceback (most recent call last):
  File "/usr/local/lib/python3.9/site-packages/django/template/base.py", line 862, in _resolve_lookup
    current = current[bit]
  File "/usr/local/lib/python3.9/site-packages/django/utils/datastructures.py", line 85, in __getitem__
    raise MultiValueDictKeyError(key)
django.utils.datastructures.MultiValueDictKeyError: 'destination'

During handling of the above exception, another exception occurred:

Traceback (most recent call last):
  File "/usr/local/lib/python3.9/site-packages/django/template/base.py", line 870, in _resolve_lookup
    current = getattr(current, bit)
AttributeError: 'QueryDict' object has no attribute 'destination'

During handling of the above exception, another exception occurred:

Traceback (most recent call last):
  File "/usr/local/lib/python3.9/site-packages/django/template/base.py", line 876, in _resolve_lookup
    current = current[int(bit)]
ValueError: invalid literal for int() with base 10: 'destination'

During handling of the above exception, another exception occurred:

Traceback (most recent call last):
  File "/usr/local/lib/python3.9/site-packages/django/template/base.py", line 881, in _resolve_lookup
    raise VariableDoesNotExist("Failed lookup for key "
django.template.base.VariableDoesNotExist: Failed lookup for key [destination] in <QueryDict: {}>
Exception while resolving variable 'people' in template 'index.html'.
Traceback (most recent call last):
  File "/usr/local/lib/python3.9/site-packages/django/utils/datastructures.py", line 83, in __getitem__
    list_ = super().__getitem__(key)
KeyError: 'people'

During handling of the above exception, another exception occurred:

Traceback (most recent call last):
  File "/usr/local/lib/python3.9/site-packages/django/template/base.py", line 862, in _resolve_lookup
    current = current[bit]
  File "/usr/local/lib/python3.9/site-packages/django/utils/datastructures.py", line 85, in __getitem__
    raise MultiValueDictKeyError(key)
django.utils.datastructures.MultiValueDictKeyError: 'people'

During handling of the above exception, another exception occurred:

Traceback (most recent call last):
  File "/usr/local/lib/python3.9/site-packages/django/template/base.py", line 870, in _resolve_lookup
    current = getattr(current, bit)
AttributeError: 'QueryDict' object has no attribute 'people'

During handling of the above exception, another exception occurred:

Traceback (most recent call last):
  File "/usr/local/lib/python3.9/site-packages/django/template/base.py", line 876, in _resolve_lookup
    current = current[int(bit)]
ValueError: invalid literal for int() with base 10: 'people'

During handling of the above exception, another exception occurred:

Traceback (most recent call last):
  File "/usr/local/lib/python3.9/site-packages/django/template/base.py", line 881, in _resolve_lookup
    raise VariableDoesNotExist("Failed lookup for key "
django.template.base.VariableDoesNotExist: Failed lookup for key [people] in <QueryDict: {}>
Exception while resolving variable 'days' in template 'index.html'.
Traceback (most recent call last):
  File "/usr/local/lib/python3.9/site-packages/django/utils/datastructures.py", line 83, in __getitem__
    list_ = super().__getitem__(key)
KeyError: 'days'

During handling of the above exception, another exception occurred:

Traceback (most recent call last):
  File "/usr/local/lib/python3.9/site-packages/django/template/base.py", line 862, in _resolve_lookup
    current = current[bit]
  File "/usr/local/lib/python3.9/site-packages/django/utils/datastructures.py", line 85, in __getitem__
    raise MultiValueDictKeyError(key)
django.utils.datastructures.MultiValueDictKeyError: 'days'

During handling of the above exception, another exception occurred:

Traceback (most recent call last):
  File "/usr/local/lib/python3.9/site-packages/django/template/base.py", line 870, in _resolve_lookup
    current = getattr(current, bit)
AttributeError: 'QueryDict' object has no attribute 'days'

During handling of the above exception, another exception occurred:

Traceback (most recent call last):
  File "/usr/local/lib/python3.9/site-packages/django/template/base.py", line 876, in _resolve_lookup
    current = current[int(bit)]
ValueError: invalid literal for int() with base 10: 'days'

During handling of the above exception, another exception occurred:

Traceback (most recent call last):
  File "/usr/local/lib/python3.9/site-packages/django/template/base.py", line 881, in _resolve_lookup
    raise VariableDoesNotExist("Failed lookup for key "
django.template.base.VariableDoesNotExist: Failed lookup for key [days] in <QueryDict: {}>
Exception while resolving variable 'budget' in template 'index.html'.
Traceback (most recent call last):
  File "/usr/local/lib/python3.9/site-packages/django/utils/datastructures.py", line 83, in __getitem__
    list_ = super().__getitem__(key)
KeyError: 'budget'

During handling of the above exception, another exception occurred:

Traceback (most recent call last):
  File "/usr/local/lib/python3.9/site-packages/django/template/base.py", line 862, in _resolve_lookup
    current = current[bit]
  File "/usr/local/lib/python3.9/site-packages/django/utils/datastructures.py", line 85, in __getitem__
    raise MultiValueDictKeyError(key)
django.utils.datastructures.MultiValueDictKeyError: 'budget'

During handling of the above exception, another exception occurred:

Traceback (most recent call last):
  File "/usr/local/lib/python3.9/site-packages/django/template/base.py", line 870, in _resolve_lookup
    current = getattr(current, bit)
AttributeError: 'QueryDict' object has no attribute 'budget'

During handling of the above exception, another exception occurred:

Traceback (most recent call last):
  File "/usr/local/lib/python3.9/site-packages/django/template/base.py", line 876, in _resolve_lookup
    current = current[int(bit)]
ValueError: invalid literal for int() with base 10: 'budget'

During handling of the above exception, another exception occurred:

Traceback (most recent call last):
  File "/usr/local/lib/python3.9/site-packages/django/template/base.py", line 881, in _resolve_lookup
    raise VariableDoesNotExist("Failed lookup for key "
django.template.base.VariableDoesNotExist: Failed lookup for key [budget] in <QueryDict: {}>
Exception while resolving variable 'currency' in template 'index.html'.
Traceback (most recent call last):
  File "/usr/local/lib/python3.9/site-packages/django/utils/datastructures.py", line 83, in __getitem__
    list_ = super().__getitem__(key)
KeyError: 'currency'

During handling of the above exception, another exception occurred:

Traceback (most recent call last):
  File "/usr/local/lib/python3.9/site-packages/django/template/base.py", line 862, in _resolve_lookup
    current = current[bit]
  File "/usr/local/lib/python3.9/site-packages/django/utils/datastructures.py", line 85, in __getitem__
    raise MultiValueDictKeyError(key)
django.utils.datastructures.MultiValueDictKeyError: 'currency'

During handling of the above exception, another exception occurred:

Traceback (most recent call last):
  File "/usr/local/lib/python3.9/site-packages/django/template/base.py", line 870, in _resolve_lookup
    current = getattr(current, bit)
AttributeError: 'QueryDict' object has no attribute 'currency'

During handling of the above exception, another exception occurred:

Traceback (most recent call last):
  File "/usr/local/lib/python3.9/site-packages/django/template/base.py", line 876, in _resolve_lookup
    current = current[int(bit)]
ValueError: invalid literal for int() with base 10: 'currency'

During handling of the above exception, another exception occurred:

Traceback (most recent call last):
  File "/usr/local/lib/python3.9/site-packages/django/template/base.py", line 881, in _resolve_lookup
    raise VariableDoesNotExist("Failed lookup for key "
django.template.base.VariableDoesNotExist: Failed lookup for key [currency] in <QueryDict: {}>
(0.001) SELECT "core_country"."id", "core_country"."country_name", "core_country"."country_code", "core_country"."currency_code", "core_country"."currency_name", "core_country"."visa_requirement", "core_country"."average_travel_cost", "core_country"."description", "core_country"."image_url" FROM "core_country" WHERE "core_country"."id" = 193 LIMIT 21; args=(193,); alias=default
Exception while resolving variable 'visa_enabled' in template 'index.html'.
Traceback (most recent call last):
  File "/usr/local/lib/python3.9/site-packages/django/utils/datastructures.py", line 83, in __getitem__
    list_ = super().__getitem__(key)
KeyError: 'visa_enabled'

During handling of the above exception, another exception occurred:

Traceback (most recent call last):
  File "/usr/local/lib/python3.9/site-packages/django/template/base.py", line 862, in _resolve_lookup
    current = current[bit]
  File "/usr/local/lib/python3.9/site-packages/django/utils/datastructures.py", line 85, in __getitem__
    raise MultiValueDictKeyError(key)
django.utils.datastructures.MultiValueDictKeyError: 'visa_enabled'

During handling of the above exception, another exception occurred:

Traceback (most recent call last):
  File "/usr/local/lib/python3.9/site-packages/django/template/base.py", line 870, in _resolve_lookup
    current = getattr(current, bit)
AttributeError: 'QueryDict' object has no attribute 'visa_enabled'

During handling of the above exception, another exception occurred:

Traceback (most recent call last):
  File "/usr/local/lib/python3.9/site-packages/django/template/base.py", line 876, in _resolve_lookup
    current = current[int(bit)]
ValueError: invalid literal for int() with base 10: 'visa_enabled'

During handling of the above exception, another exception occurred:

Traceback (most recent call last):
  File "/usr/local/lib/python3.9/site-packages/django/template/base.py", line 881, in _resolve_lookup
    raise VariableDoesNotExist("Failed lookup for key "
django.template.base.VariableDoesNotExist: Failed lookup for key [visa_enabled] in <QueryDict: {}>
Exception while resolving variable 'get_error_message' in template 'index.html'.
Traceback (most recent call last):
  File "/usr/local/lib/python3.9/site-packages/django/template/base.py", line 862, in _resolve_lookup
    current = current[bit]
TypeError: 'FallbackStorage' object is not subscriptable

During handling of the above exception, another exception occurred:

Traceback (most recent call last):
  File "/usr/local/lib/python3.9/site-packages/django/template/base.py", line 870, in _resolve_lookup
    current = getattr(current, bit)
AttributeError: 'FallbackStorage' object has no attribute 'get_error_message'

During handling of the above exception, another exception occurred:

Traceback (most recent call last):
  File "/usr/local/lib/python3.9/site-packages/django/template/base.py", line 876, in _resolve_lookup
    current = current[int(bit)]
ValueError: invalid literal for int() with base 10: 'get_error_message'

During handling of the above exception, another exception occurred:

Traceback (most recent call last):
  File "/usr/local/lib/python3.9/site-packages/django/template/base.py", line 881, in _resolve_lookup
    raise VariableDoesNotExist("Failed lookup for key "
django.template.base.VariableDoesNotExist: Failed lookup for key [get_error_message] in <FallbackStorage: request=<WSGIRequest: GET '/'>>
Exception while resolving variable 'searched' in template 'index.html'.
Traceback (most recent call last):
  File "/usr/local/lib/python3.9/site-packages/django/template/base.py", line 862, in _resolve_lookup
    current = current[bit]
  File "/usr/local/lib/python3.9/site-packages/django/template/context.py", line 83, in __getitem__
    raise KeyError(key)
KeyError: 'searched'

During handling of the above exception, another exception occurred:

Traceback (most recent call last):
  File "/usr/local/lib/python3.9/site-packages/django/template/base.py", line 868, in _resolve_lookup
    if isinstance(current, BaseContext) and getattr(type(current), bit):
AttributeError: type object 'RequestContext' has no attribute 'searched'

During handling of the above exception, another exception occurred:

Traceback (most recent call last):
  File "/usr/local/lib/python3.9/site-packages/django/template/base.py", line 876, in _resolve_lookup
    current = current[int(bit)]
ValueError: invalid literal for int() with base 10: 'searched'

During handling of the above exception, another exception occurred:

Traceback (most recent call last):
  File "/usr/local/lib/python3.9/site-packages/django/template/base.py", line 881, in _resolve_lookup
    raise VariableDoesNotExist("Failed lookup for key "
django.template.base.VariableDoesNotExist: Failed lookup for key [searched] in [{'True': True, 'False': False, 'None': None}, {'csrf_token': <SimpleLazyObject: 'cEMUT2HOcwskI7Ga8syHr09BBOL2VYIDx06xzbCp5KwZzdd77a4qizPfT4vgIvfC'>, 'request': <WSGIRequest: GET '/'>, 'user': <SimpleLazyObject: <CustomUser: user>>, 'perms': PermWrapper(<SimpleLazyObject: <CustomUser: user>>), 'messages': <FallbackStorage: request=<WSGIRequest: GET '/'>>, 'DEFAULT_MESSAGE_LEVELS': {'DEBUG': 10, 'INFO': 20, 'SUCCESS': 25, 'WARNING': 30, 'ERROR': 40}}, {}, {}]
"GET / HTTP/1.1" 200 20503
(0.001) SELECT "django_session"."session_key", "django_session"."session_data", "django_session"."expire_date" FROM "django_session" WHERE ("django_session"."expire_date" > '2025-03-25T16:08:50.642341+00:00'::timestamptz AND "django_session"."session_key" = 't3u25nv8ifdkj0um0qal6s4s0zj2zawi') LIMIT 21; args=(datetime.datetime(2025, 3, 25, 16, 8, 50, 642341, tzinfo=datetime.timezone.utc), 't3u25nv8ifdkj0um0qal6s4s0zj2zawi'); alias=default
(0.001) SELECT "core_customuser"."id", "core_customuser"."password", "core_customuser"."last_login", "core_customuser"."is_superuser", "core_customuser"."username", "core_customuser"."first_name", "core_customuser"."last_name", "core_customuser"."email", "core_customuser"."is_staff", "core_customuser"."is_active", "core_customuser"."date_joined", "core_customuser"."country_id", "core_customuser"."budget", "core_customuser"."currency" FROM "core_customuser" WHERE "core_customuser"."id" = 2 LIMIT 21; args=(2,); alias=default
Exception while resolving variable 'login_form' in template 'index.html'.
Traceback (most recent call last):
  File "/usr/local/lib/python3.9/site-packages/django/template/base.py", line 862, in _resolve_lookup
    current = current[bit]
  File "/usr/local/lib/python3.9/site-packages/django/template/context.py", line 83, in __getitem__
    raise KeyError(key)
KeyError: 'login_form'

During handling of the above exception, another exception occurred:

Traceback (most recent call last):
  File "/usr/local/lib/python3.9/site-packages/django/template/base.py", line 868, in _resolve_lookup
    if isinstance(current, BaseContext) and getattr(type(current), bit):
AttributeError: type object 'RequestContext' has no attribute 'login_form'

During handling of the above exception, another exception occurred:

Traceback (most recent call last):
  File "/usr/local/lib/python3.9/site-packages/django/template/base.py", line 876, in _resolve_lookup
    current = current[int(bit)]
ValueError: invalid literal for int() with base 10: 'login_form'

During handling of the above exception, another exception occurred:

Traceback (most recent call last):
  File "/usr/local/lib/python3.9/site-packages/django/template/base.py", line 881, in _resolve_lookup
    raise VariableDoesNotExist("Failed lookup for key "
django.template.base.VariableDoesNotExist: Failed lookup for key [login_form] in [{'True': True, 'False': False, 'None': None}, {'csrf_token': <SimpleLazyObject: <function csrf.<locals>._get_val at 0x7fbda01b2c10>>, 'request': <WSGIRequest: GET '/'>, 'user': <SimpleLazyObject: <CustomUser: user>>, 'perms': PermWrapper(<SimpleLazyObject: <CustomUser: user>>), 'messages': <FallbackStorage: request=<WSGIRequest: GET '/'>>, 'DEFAULT_MESSAGE_LEVELS': {'DEBUG': 10, 'INFO': 20, 'SUCCESS': 25, 'WARNING': 30, 'ERROR': 40}}, {}, {}, {}]
Exception while resolving variable 'reg_form' in template 'index.html'.
Traceback (most recent call last):
  File "/usr/local/lib/python3.9/site-packages/django/template/base.py", line 862, in _resolve_lookup
    current = current[bit]
  File "/usr/local/lib/python3.9/site-packages/django/template/context.py", line 83, in __getitem__
    raise KeyError(key)
KeyError: 'reg_form'

During handling of the above exception, another exception occurred:

Traceback (most recent call last):
  File "/usr/local/lib/python3.9/site-packages/django/template/base.py", line 868, in _resolve_lookup
    if isinstance(current, BaseContext) and getattr(type(current), bit):
AttributeError: type object 'RequestContext' has no attribute 'reg_form'

During handling of the above exception, another exception occurred:

Traceback (most recent call last):
  File "/usr/local/lib/python3.9/site-packages/django/template/base.py", line 876, in _resolve_lookup
    current = current[int(bit)]
ValueError: invalid literal for int() with base 10: 'reg_form'

During handling of the above exception, another exception occurred:

Traceback (most recent call last):
  File "/usr/local/lib/python3.9/site-packages/django/template/base.py", line 881, in _resolve_lookup
    raise VariableDoesNotExist("Failed lookup for key "
django.template.base.VariableDoesNotExist: Failed lookup for key [reg_form] in [{'True': True, 'False': False, 'None': None}, {'csrf_token': <SimpleLazyObject: 'hUMOvXAQ9xtzLBJjFHPpu7QMs1dQmlSgCg6rb6vr2LxeCHggEpl8lGwqKhX49Spf'>, 'request': <WSGIRequest: GET '/'>, 'user': <SimpleLazyObject: <CustomUser: user>>, 'perms': PermWrapper(<SimpleLazyObject: <CustomUser: user>>), 'messages': <FallbackStorage: request=<WSGIRequest: GET '/'>>, 'DEFAULT_MESSAGE_LEVELS': {'DEBUG': 10, 'INFO': 20, 'SUCCESS': 25, 'WARNING': 30, 'ERROR': 40}}, {}, {}, {}]
Exception while resolving variable 'destination' in template 'index.html'.
Traceback (most recent call last):
  File "/usr/local/lib/python3.9/site-packages/django/utils/datastructures.py", line 83, in __getitem__
    list_ = super().__getitem__(key)
KeyError: 'destination'

During handling of the above exception, another exception occurred:

Traceback (most recent call last):
  File "/usr/local/lib/python3.9/site-packages/django/template/base.py", line 862, in _resolve_lookup
    current = current[bit]
  File "/usr/local/lib/python3.9/site-packages/django/utils/datastructures.py", line 85, in __getitem__
    raise MultiValueDictKeyError(key)
django.utils.datastructures.MultiValueDictKeyError: 'destination'

During handling of the above exception, another exception occurred:

Traceback (most recent call last):
  File "/usr/local/lib/python3.9/site-packages/django/template/base.py", line 870, in _resolve_lookup
    current = getattr(current, bit)
AttributeError: 'QueryDict' object has no attribute 'destination'

During handling of the above exception, another exception occurred:

Traceback (most recent call last):
  File "/usr/local/lib/python3.9/site-packages/django/template/base.py", line 876, in _resolve_lookup
    current = current[int(bit)]
ValueError: invalid literal for int() with base 10: 'destination'

During handling of the above exception, another exception occurred:

Traceback (most recent call last):
  File "/usr/local/lib/python3.9/site-packages/django/template/base.py", line 881, in _resolve_lookup
    raise VariableDoesNotExist("Failed lookup for key "
django.template.base.VariableDoesNotExist: Failed lookup for key [destination] in <QueryDict: {}>
Exception while resolving variable 'people' in template 'index.html'.
Traceback (most recent call last):
  File "/usr/local/lib/python3.9/site-packages/django/utils/datastructures.py", line 83, in __getitem__
    list_ = super().__getitem__(key)
KeyError: 'people'

During handling of the above exception, another exception occurred:

Traceback (most recent call last):
  File "/usr/local/lib/python3.9/site-packages/django/template/base.py", line 862, in _resolve_lookup
    current = current[bit]
  File "/usr/local/lib/python3.9/site-packages/django/utils/datastructures.py", line 85, in __getitem__
    raise MultiValueDictKeyError(key)
django.utils.datastructures.MultiValueDictKeyError: 'people'

During handling of the above exception, another exception occurred:

Traceback (most recent call last):
  File "/usr/local/lib/python3.9/site-packages/django/template/base.py", line 870, in _resolve_lookup
    current = getattr(current, bit)
AttributeError: 'QueryDict' object has no attribute 'people'

During handling of the above exception, another exception occurred:

Traceback (most recent call last):
  File "/usr/local/lib/python3.9/site-packages/django/template/base.py", line 876, in _resolve_lookup
    current = current[int(bit)]
ValueError: invalid literal for int() with base 10: 'people'

During handling of the above exception, another exception occurred:

Traceback (most recent call last):
  File "/usr/local/lib/python3.9/site-packages/django/template/base.py", line 881, in _resolve_lookup
    raise VariableDoesNotExist("Failed lookup for key "
django.template.base.VariableDoesNotExist: Failed lookup for key [people] in <QueryDict: {}>
Exception while resolving variable 'days' in template 'index.html'.
Traceback (most recent call last):
  File "/usr/local/lib/python3.9/site-packages/django/utils/datastructures.py", line 83, in __getitem__
    list_ = super().__getitem__(key)
KeyError: 'days'

During handling of the above exception, another exception occurred:

Traceback (most recent call last):
  File "/usr/local/lib/python3.9/site-packages/django/template/base.py", line 862, in _resolve_lookup
    current = current[bit]
  File "/usr/local/lib/python3.9/site-packages/django/utils/datastructures.py", line 85, in __getitem__
    raise MultiValueDictKeyError(key)
django.utils.datastructures.MultiValueDictKeyError: 'days'

During handling of the above exception, another exception occurred:

Traceback (most recent call last):
  File "/usr/local/lib/python3.9/site-packages/django/template/base.py", line 870, in _resolve_lookup
    current = getattr(current, bit)
AttributeError: 'QueryDict' object has no attribute 'days'

During handling of the above exception, another exception occurred:

Traceback (most recent call last):
  File "/usr/local/lib/python3.9/site-packages/django/template/base.py", line 876, in _resolve_lookup
    current = current[int(bit)]
ValueError: invalid literal for int() with base 10: 'days'

During handling of the above exception, another exception occurred:

Traceback (most recent call last):
  File "/usr/local/lib/python3.9/site-packages/django/template/base.py", line 881, in _resolve_lookup
    raise VariableDoesNotExist("Failed lookup for key "
django.template.base.VariableDoesNotExist: Failed lookup for key [days] in <QueryDict: {}>
Exception while resolving variable 'budget' in template 'index.html'.
Traceback (most recent call last):
  File "/usr/local/lib/python3.9/site-packages/django/utils/datastructures.py", line 83, in __getitem__
    list_ = super().__getitem__(key)
KeyError: 'budget'

During handling of the above exception, another exception occurred:

Traceback (most recent call last):
  File "/usr/local/lib/python3.9/site-packages/django/template/base.py", line 862, in _resolve_lookup
    current = current[bit]
  File "/usr/local/lib/python3.9/site-packages/django/utils/datastructures.py", line 85, in __getitem__
    raise MultiValueDictKeyError(key)
django.utils.datastructures.MultiValueDictKeyError: 'budget'

During handling of the above exception, another exception occurred:

Traceback (most recent call last):
  File "/usr/local/lib/python3.9/site-packages/django/template/base.py", line 870, in _resolve_lookup
    current = getattr(current, bit)
AttributeError: 'QueryDict' object has no attribute 'budget'

During handling of the above exception, another exception occurred:

Traceback (most recent call last):
  File "/usr/local/lib/python3.9/site-packages/django/template/base.py", line 876, in _resolve_lookup
    current = current[int(bit)]
ValueError: invalid literal for int() with base 10: 'budget'

During handling of the above exception, another exception occurred:

Traceback (most recent call last):
  File "/usr/local/lib/python3.9/site-packages/django/template/base.py", line 881, in _resolve_lookup
    raise VariableDoesNotExist("Failed lookup for key "
django.template.base.VariableDoesNotExist: Failed lookup for key [budget] in <QueryDict: {}>
Exception while resolving variable 'currency' in template 'index.html'.
Traceback (most recent call last):
  File "/usr/local/lib/python3.9/site-packages/django/utils/datastructures.py", line 83, in __getitem__
    list_ = super().__getitem__(key)
KeyError: 'currency'

During handling of the above exception, another exception occurred:

Traceback (most recent call last):
  File "/usr/local/lib/python3.9/site-packages/django/template/base.py", line 862, in _resolve_lookup
    current = current[bit]
  File "/usr/local/lib/python3.9/site-packages/django/utils/datastructures.py", line 85, in __getitem__
    raise MultiValueDictKeyError(key)
django.utils.datastructures.MultiValueDictKeyError: 'currency'

During handling of the above exception, another exception occurred:

Traceback (most recent call last):
  File "/usr/local/lib/python3.9/site-packages/django/template/base.py", line 870, in _resolve_lookup
    current = getattr(current, bit)
AttributeError: 'QueryDict' object has no attribute 'currency'

During handling of the above exception, another exception occurred:

Traceback (most recent call last):
  File "/usr/local/lib/python3.9/site-packages/django/template/base.py", line 876, in _resolve_lookup
    current = current[int(bit)]
ValueError: invalid literal for int() with base 10: 'currency'

During handling of the above exception, another exception occurred:

Traceback (most recent call last):
  File "/usr/local/lib/python3.9/site-packages/django/template/base.py", line 881, in _resolve_lookup
    raise VariableDoesNotExist("Failed lookup for key "
django.template.base.VariableDoesNotExist: Failed lookup for key [currency] in <QueryDict: {}>
(0.001) SELECT "core_country"."id", "core_country"."country_name", "core_country"."country_code", "core_country"."currency_code", "core_country"."currency_name", "core_country"."visa_requirement", "core_country"."average_travel_cost", "core_country"."description", "core_country"."image_url" FROM "core_country" WHERE "core_country"."id" = 193 LIMIT 21; args=(193,); alias=default
Exception while resolving variable 'visa_enabled' in template 'index.html'.
Traceback (most recent call last):
  File "/usr/local/lib/python3.9/site-packages/django/utils/datastructures.py", line 83, in __getitem__
    list_ = super().__getitem__(key)
KeyError: 'visa_enabled'

During handling of the above exception, another exception occurred:

Traceback (most recent call last):
  File "/usr/local/lib/python3.9/site-packages/django/template/base.py", line 862, in _resolve_lookup
    current = current[bit]
  File "/usr/local/lib/python3.9/site-packages/django/utils/datastructures.py", line 85, in __getitem__
    raise MultiValueDictKeyError(key)
django.utils.datastructures.MultiValueDictKeyError: 'visa_enabled'

During handling of the above exception, another exception occurred:

Traceback (most recent call last):
  File "/usr/local/lib/python3.9/site-packages/django/template/base.py", line 870, in _resolve_lookup
    current = getattr(current, bit)
AttributeError: 'QueryDict' object has no attribute 'visa_enabled'

During handling of the above exception, another exception occurred:

Traceback (most recent call last):
  File "/usr/local/lib/python3.9/site-packages/django/template/base.py", line 876, in _resolve_lookup
    current = current[int(bit)]
ValueError: invalid literal for int() with base 10: 'visa_enabled'

During handling of the above exception, another exception occurred:

Traceback (most recent call last):
  File "/usr/local/lib/python3.9/site-packages/django/template/base.py", line 881, in _resolve_lookup
    raise VariableDoesNotExist("Failed lookup for key "
django.template.base.VariableDoesNotExist: Failed lookup for key [visa_enabled] in <QueryDict: {}>
Exception while resolving variable 'get_error_message' in template 'index.html'.
Traceback (most recent call last):
  File "/usr/local/lib/python3.9/site-packages/django/template/base.py", line 862, in _resolve_lookup
    current = current[bit]
TypeError: 'FallbackStorage' object is not subscriptable

During handling of the above exception, another exception occurred:

Traceback (most recent call last):
  File "/usr/local/lib/python3.9/site-packages/django/template/base.py", line 870, in _resolve_lookup
    current = getattr(current, bit)
AttributeError: 'FallbackStorage' object has no attribute 'get_error_message'

During handling of the above exception, another exception occurred:

Traceback (most recent call last):
  File "/usr/local/lib/python3.9/site-packages/django/template/base.py", line 876, in _resolve_lookup
    current = current[int(bit)]
ValueError: invalid literal for int() with base 10: 'get_error_message'

During handling of the above exception, another exception occurred:

Traceback (most recent call last):
  File "/usr/local/lib/python3.9/site-packages/django/template/base.py", line 881, in _resolve_lookup
    raise VariableDoesNotExist("Failed lookup for key "
django.template.base.VariableDoesNotExist: Failed lookup for key [get_error_message] in <FallbackStorage: request=<WSGIRequest: GET '/'>>
Exception while resolving variable 'searched' in template 'index.html'.
Traceback (most recent call last):
  File "/usr/local/lib/python3.9/site-packages/django/template/base.py", line 862, in _resolve_lookup
    current = current[bit]
  File "/usr/local/lib/python3.9/site-packages/django/template/context.py", line 83, in __getitem__
    raise KeyError(key)
KeyError: 'searched'

During handling of the above exception, another exception occurred:

Traceback (most recent call last):
  File "/usr/local/lib/python3.9/site-packages/django/template/base.py", line 868, in _resolve_lookup
    if isinstance(current, BaseContext) and getattr(type(current), bit):
AttributeError: type object 'RequestContext' has no attribute 'searched'

During handling of the above exception, another exception occurred:

Traceback (most recent call last):
  File "/usr/local/lib/python3.9/site-packages/django/template/base.py", line 876, in _resolve_lookup
    current = current[int(bit)]
ValueError: invalid literal for int() with base 10: 'searched'

During handling of the above exception, another exception occurred:

Traceback (most recent call last):
  File "/usr/local/lib/python3.9/site-packages/django/template/base.py", line 881, in _resolve_lookup
    raise VariableDoesNotExist("Failed lookup for key "
django.template.base.VariableDoesNotExist: Failed lookup for key [searched] in [{'True': True, 'False': False, 'None': None}, {'csrf_token': <SimpleLazyObject: 'hUMOvXAQ9xtzLBJjFHPpu7QMs1dQmlSgCg6rb6vr2LxeCHggEpl8lGwqKhX49Spf'>, 'request': <WSGIRequest: GET '/'>, 'user': <SimpleLazyObject: <CustomUser: user>>, 'perms': PermWrapper(<SimpleLazyObject: <CustomUser: user>>), 'messages': <FallbackStorage: request=<WSGIRequest: GET '/'>>, 'DEFAULT_MESSAGE_LEVELS': {'DEBUG': 10, 'INFO': 20, 'SUCCESS': 25, 'WARNING': 30, 'ERROR': 40}}, {}, {}]
"GET / HTTP/1.1" 200 20503
Not Found: /serviceworker.js
"GET /serviceworker.js HTTP/1.1" 404 3346
(0.001) SELECT "django_session"."session_key", "django_session"."session_data", "django_session"."expire_date" FROM "django_session" WHERE ("django_session"."expire_date" > '2025-03-25T16:08:55.841106+00:00'::timestamptz AND "django_session"."session_key" = 't3u25nv8ifdkj0um0qal6s4s0zj2zawi') LIMIT 21; args=(datetime.datetime(2025, 3, 25, 16, 8, 55, 841106, tzinfo=datetime.timezone.utc), 't3u25nv8ifdkj0um0qal6s4s0zj2zawi'); alias=default
(0.000) SELECT "core_customuser"."id", "core_customuser"."password", "core_customuser"."last_login", "core_customuser"."is_superuser", "core_customuser"."username", "core_customuser"."first_name", "core_customuser"."last_name", "core_customuser"."email", "core_customuser"."is_staff", "core_customuser"."is_active", "core_customuser"."date_joined", "core_customuser"."country_id", "core_customuser"."budget", "core_customuser"."currency" FROM "core_customuser" WHERE "core_customuser"."id" = 2 LIMIT 21; args=(2,); alias=default
Exception while resolving variable 'login_form' in template 'utils/profile.html'.
Traceback (most recent call last):
  File "/usr/local/lib/python3.9/site-packages/django/template/base.py", line 862, in _resolve_lookup
    current = current[bit]
  File "/usr/local/lib/python3.9/site-packages/django/template/context.py", line 83, in __getitem__
    raise KeyError(key)
KeyError: 'login_form'

During handling of the above exception, another exception occurred:

Traceback (most recent call last):
  File "/usr/local/lib/python3.9/site-packages/django/template/base.py", line 868, in _resolve_lookup
    if isinstance(current, BaseContext) and getattr(type(current), bit):
AttributeError: type object 'RequestContext' has no attribute 'login_form'

During handling of the above exception, another exception occurred:

Traceback (most recent call last):
  File "/usr/local/lib/python3.9/site-packages/django/template/base.py", line 876, in _resolve_lookup
    current = current[int(bit)]
ValueError: invalid literal for int() with base 10: 'login_form'

During handling of the above exception, another exception occurred:

Traceback (most recent call last):
  File "/usr/local/lib/python3.9/site-packages/django/template/base.py", line 881, in _resolve_lookup
    raise VariableDoesNotExist("Failed lookup for key "
django.template.base.VariableDoesNotExist: Failed lookup for key [login_form] in [{'True': True, 'False': False, 'None': None}, {'csrf_token': <SimpleLazyObject: <function csrf.<locals>._get_val at 0x7fbda01de4c0>>, 'request': <WSGIRequest: GET '/profile/'>, 'user': <SimpleLazyObject: <CustomUser: user>>, 'perms': PermWrapper(<SimpleLazyObject: <CustomUser: user>>), 'messages': <FallbackStorage: request=<WSGIRequest: GET '/profile/'>>, 'DEFAULT_MESSAGE_LEVELS': {'DEBUG': 10, 'INFO': 20, 'SUCCESS': 25, 'WARNING': 30, 'ERROR': 40}}, {}, {}, {}]
Exception while resolving variable 'reg_form' in template 'utils/profile.html'.
Traceback (most recent call last):
  File "/usr/local/lib/python3.9/site-packages/django/template/base.py", line 862, in _resolve_lookup
    current = current[bit]
  File "/usr/local/lib/python3.9/site-packages/django/template/context.py", line 83, in __getitem__
    raise KeyError(key)
KeyError: 'reg_form'

During handling of the above exception, another exception occurred:

Traceback (most recent call last):
  File "/usr/local/lib/python3.9/site-packages/django/template/base.py", line 868, in _resolve_lookup
    if isinstance(current, BaseContext) and getattr(type(current), bit):
AttributeError: type object 'RequestContext' has no attribute 'reg_form'

During handling of the above exception, another exception occurred:

Traceback (most recent call last):
  File "/usr/local/lib/python3.9/site-packages/django/template/base.py", line 876, in _resolve_lookup
    current = current[int(bit)]
ValueError: invalid literal for int() with base 10: 'reg_form'

During handling of the above exception, another exception occurred:

Traceback (most recent call last):
  File "/usr/local/lib/python3.9/site-packages/django/template/base.py", line 881, in _resolve_lookup
    raise VariableDoesNotExist("Failed lookup for key "
django.template.base.VariableDoesNotExist: Failed lookup for key [reg_form] in [{'True': True, 'False': False, 'None': None}, {'csrf_token': <SimpleLazyObject: 'jWTOlm3c2PGsJX1EWktzBkOxTUiuA56EEidr1vYNV3K7A3yBV2ZisTubba2InCDD'>, 'request': <WSGIRequest: GET '/profile/'>, 'user': <SimpleLazyObject: <CustomUser: user>>, 'perms': PermWrapper(<SimpleLazyObject: <CustomUser: user>>), 'messages': <FallbackStorage: request=<WSGIRequest: GET '/profile/'>>, 'DEFAULT_MESSAGE_LEVELS': {'DEBUG': 10, 'INFO': 20, 'SUCCESS': 25, 'WARNING': 30, 'ERROR': 40}}, {}, {}, {}]
(0.001) SELECT "core_country"."id", "core_country"."country_name", "core_country"."country_code", "core_country"."currency_code", "core_country"."currency_name", "core_country"."visa_requirement", "core_country"."average_travel_cost", "core_country"."description", "core_country"."image_url" FROM "core_country" WHERE "core_country"."id" = 193 LIMIT 21; args=(193,); alias=default
"GET /profile/ HTTP/1.1" 200 15385
Not Found: /favicon.ico
"GET /favicon.ico HTTP/1.1" 404 3331
Not Found: /serviceworker.js
"GET /serviceworker.js HTTP/1.1" 404 3346
Not Found: /serviceworker.js
"GET /serviceworker.js HTTP/1.1" 404 3346
(0.001) SELECT "core_country"."id", "core_country"."country_name", "core_country"."country_code", "core_country"."currency_code", "core_country"."currency_name", "core_country"."visa_requirement", "core_country"."average_travel_cost", "core_country"."description", "core_country"."image_url" FROM "core_country" WHERE (UPPER("core_country"."currency_name"::text) LIKE UPPER('%U%') OR UPPER("core_country"."currency_code"::text) LIKE UPPER('%U%')) LIMIT 50; args=('%U%', '%U%'); alias=default
"GET /api/currency-search/?q=U HTTP/1.1" 200 1486
(0.001) SELECT "core_country"."id", "core_country"."country_name", "core_country"."country_code", "core_country"."currency_code", "core_country"."currency_name", "core_country"."visa_requirement", "core_country"."average_travel_cost", "core_country"."description", "core_country"."image_url" FROM "core_country" WHERE (UPPER("core_country"."currency_name"::text) LIKE UPPER('%US%') OR UPPER("core_country"."currency_code"::text) LIKE UPPER('%US%')) LIMIT 50; args=('%US%', '%US%'); alias=default
"GET /api/currency-search/?q=US HTTP/1.1" 200 256
(0.001) SELECT "core_country"."id", "core_country"."country_name", "core_country"."country_code", "core_country"."currency_code", "core_country"."currency_name", "core_country"."visa_requirement", "core_country"."average_travel_cost", "core_country"."description", "core_country"."image_url" FROM "core_country" WHERE (UPPER("core_country"."currency_name"::text) LIKE UPPER('%USD%') OR UPPER("core_country"."currency_code"::text) LIKE UPPER('%USD%')) LIMIT 50; args=('%USD%', '%USD%'); alias=default
"GET /api/currency-search/?q=USD HTTP/1.1" 200 46
Not Found: /serviceworker.js
"GET /serviceworker.js HTTP/1.1" 404 3346
(0.001) SELECT "django_session"."session_key", "django_session"."session_data", "django_session"."expire_date" FROM "django_session" WHERE ("django_session"."expire_date" > '2025-03-25T16:10:14.503799+00:00'::timestamptz AND "django_session"."session_key" = 't3u25nv8ifdkj0um0qal6s4s0zj2zawi') LIMIT 21; args=(datetime.datetime(2025, 3, 25, 16, 10, 14, 503799, tzinfo=datetime.timezone.utc), 't3u25nv8ifdkj0um0qal6s4s0zj2zawi'); alias=default
(0.000) SELECT "core_customuser"."id", "core_customuser"."password", "core_customuser"."last_login", "core_customuser"."is_superuser", "core_customuser"."username", "core_customuser"."first_name", "core_customuser"."last_name", "core_customuser"."email", "core_customuser"."is_staff", "core_customuser"."is_active", "core_customuser"."date_joined", "core_customuser"."country_id", "core_customuser"."budget", "core_customuser"."currency" FROM "core_customuser" WHERE "core_customuser"."id" = 2 LIMIT 21; args=(2,); alias=default
(0.001) SELECT "core_country"."id", "core_country"."country_name", "core_country"."country_code", "core_country"."currency_code", "core_country"."currency_name", "core_country"."visa_requirement", "core_country"."average_travel_cost", "core_country"."description", "core_country"."image_url" FROM "core_country" WHERE "core_country"."id" = 193 LIMIT 21; args=(193,); alias=default
File /usr/local/lib/python3.9/site-packages/openai/api_resources/experimental/__init__.py first seen with mtime 1742333653.0
File /usr/local/lib/python3.9/site-packages/openai/api_resources/experimental/completion_config.py first seen with mtime 1742333653.0
File /usr/local/lib/python3.9/site-packages/openai/object_classes.py first seen with mtime 1742333653.0
(0.000) UPDATE "django_session" SET "session_data" = '.eJx1Vdtu4zYQ_RVCD-mLLcuW7cgBjCKLLJC09T5sk0WL7kKgpJHEhCJVkvIlQf69M5SSKLtbIAEozvWcOUM_BSnvXJ12FkwqiuAiWAST8V3G8wdQZCjuuap0mGvljMhCcgkHqw13ugD5YfB9l6Dmtsbo-SYuk2gRRcWa5-fzLCmzBLJ4GfOyyOJ4sd7AOo6LnC_ieL1YJ_NlkkTLLFpGq3W5zACTWuAmr1MDtpPOBhf_PAWt5DmkijeAJX7vuOTsj65pO4PuBVgnFHdCKzTu0HaygpMBD8HFahK0_BhczCdB1hUVOGpyFUXokHfGgMpPeHP359X7VOkPxlxblwqV_txpPl-FETmpPRgHRUruo2uMdXD0xemK9TlFwytIOyPxvnautRezmb-zYacsorY1DqKZtbV2ejpfnp9H6-Vms06izbTgsFxvkhUAnP-aG91uASem29NZbrfY4cmaKjsrhds2_HhWNtv7tjoTR1Fsd_Eh3t3fnXaPH5Ld9eFYXv9WZ83nffbXMSmvh_-rj_Gnq5vV7vbhsHv8lGCkFNnWZNNlGIXx2b_bJDo7bOdREvXE5Ua0www-HlupDbDxoCas5cYxXbLxhMBxIQf8sxGxswcKnUofOkNPxA-StPBtEsAegQ5nZzjypI0b-H4KpD6kL4PuyW9EkaJbhdpZRnQhu2NnaGYr_HyeBKXWxU_jF9_Hn6_G8XHUx9uaGtgLywn89AsdJgF9DzN_-h-XspMyHfkNlq_qq7q0jLPPnUWiFMuFE4-gJuykO5bjBW9beWKlNgw_wAcxpxmmEu6V4JDd1mDgF8uUZgqgIJdKM6FYC8ZqRd-coWRx0bgDhumgybi1p5DdOF8oA1ZoBaw0umGuBvRusKwfJDZjWK0bH6jLUuRAue876zBtCQfWCNU51DIButWUDKSoRCbhfe89sIYCa74HjN5zKQqUjPXD7b0dk8DRZc0afJtq-9aUUA7fIwRYeBglo0040bV-ZWOCWQ3kaHlNO7XIKvO7hfI0GgPxz3YERZBj2eGb54tTlaIzXpyv2K3jVGRUArkshWmwEwOuM4qViLd2zAl8MZ3FHlTBeI4kNrrokwmF-ZuX82h4njQsO4yXS1Sm9UQhqu9L-ybjiNGb11dBIQjSkBWqQr57RkhrJAu00JE8eqZ7jAbgB25fKBXWdlzlELK_X2b1pkIs9jqeBTsAPFgkVFBS3XOFb5lSJEF8JnpsX7xYqYTXjuDyDc1N04hqYHvAf4nFRN5fHSDDWBiIMH0W_uYQsrtW-y0xGvFNsD_cApw-8t4LBSOxP-W8_tsTAXQjrpG_DM0VATsIV3vaDzXgyhgUqERTD-JSHrBjlteQP_gMtEhIwmiqOI6B7VZLEpbFvSBReKnnNb0sBS0ctsilpZWs8EFiogC_1HyvcUA-gcbfFpq89TmxtwZVkNMG-iZbUFw6KkAjaVqeu558ngkp3Imy9f2z0WKQjKjzskPFQhg8P397_g8VvNc_:1tx6rJ:odHQeuYbgushBNlJTfGXIl9yJ8l3B7nHij8kwEtetXA', "expire_date" = '2025-04-08T16:10:33.866268+00:00'::timestamptz WHERE "django_session"."session_key" = 't3u25nv8ifdkj0um0qal6s4s0zj2zawi'; args=('.eJx1Vdtu4zYQ_RVCD-mLLcuW7cgBjCKLLJC09T5sk0WL7kKgpJHEhCJVkvIlQf69M5SSKLtbIAEozvWcOUM_BSnvXJ12FkwqiuAiWAST8V3G8wdQZCjuuap0mGvljMhCcgkHqw13ugD5YfB9l6Dmtsbo-SYuk2gRRcWa5-fzLCmzBLJ4GfOyyOJ4sd7AOo6LnC_ieL1YJ_NlkkTLLFpGq3W5zACTWuAmr1MDtpPOBhf_PAWt5DmkijeAJX7vuOTsj65pO4PuBVgnFHdCKzTu0HaygpMBD8HFahK0_BhczCdB1hUVOGpyFUXokHfGgMpPeHP359X7VOkPxlxblwqV_txpPl-FETmpPRgHRUruo2uMdXD0xemK9TlFwytIOyPxvnautRezmb-zYacsorY1DqKZtbV2ejpfnp9H6-Vms06izbTgsFxvkhUAnP-aG91uASem29NZbrfY4cmaKjsrhds2_HhWNtv7tjoTR1Fsd_Eh3t3fnXaPH5Ld9eFYXv9WZ83nffbXMSmvh_-rj_Gnq5vV7vbhsHv8lGCkFNnWZNNlGIXx2b_bJDo7bOdREvXE5Ua0www-HlupDbDxoCas5cYxXbLxhMBxIQf8sxGxswcKnUofOkNPxA-StPBtEsAegQ5nZzjypI0b-H4KpD6kL4PuyW9EkaJbhdpZRnQhu2NnaGYr_HyeBKXWxU_jF9_Hn6_G8XHUx9uaGtgLywn89AsdJgF9DzN_-h-XspMyHfkNlq_qq7q0jLPPnUWiFMuFE4-gJuykO5bjBW9beWKlNgw_wAcxpxmmEu6V4JDd1mDgF8uUZgqgIJdKM6FYC8ZqRd-coWRx0bgDhumgybi1p5DdOF8oA1ZoBaw0umGuBvRusKwfJDZjWK0bH6jLUuRAue876zBtCQfWCNU51DIButWUDKSoRCbhfe89sIYCa74HjN5zKQqUjPXD7b0dk8DRZc0afJtq-9aUUA7fIwRYeBglo0040bV-ZWOCWQ3kaHlNO7XIKvO7hfI0GgPxz3YERZBj2eGb54tTlaIzXpyv2K3jVGRUArkshWmwEwOuM4qViLd2zAl8MZ3FHlTBeI4kNrrokwmF-ZuX82h4njQsO4yXS1Sm9UQhqu9L-ybjiNGb11dBIQjSkBWqQr57RkhrJAu00JE8eqZ7jAbgB25fKBXWdlzlELK_X2b1pkIs9jqeBTsAPFgkVFBS3XOFb5lSJEF8JnpsX7xYqYTXjuDyDc1N04hqYHvAf4nFRN5fHSDDWBiIMH0W_uYQsrtW-y0xGvFNsD_cApw-8t4LBSOxP-W8_tsTAXQjrpG_DM0VATsIV3vaDzXgyhgUqERTD-JSHrBjlteQP_gMtEhIwmiqOI6B7VZLEpbFvSBReKnnNb0sBS0ctsilpZWs8EFiogC_1HyvcUA-gcbfFpq89TmxtwZVkNMG-iZbUFw6KkAjaVqeu558ngkp3Imy9f2z0WKQjKjzskPFQhg8P397_g8VvNc_:1tx6rJ:odHQeuYbgushBNlJTfGXIl9yJ8l3B7nHij8kwEtetXA', datetime.datetime(2025, 4, 8, 16, 10, 33, 866268, tzinfo=datetime.timezone.utc), 't3u25nv8ifdkj0um0qal6s4s0zj2zawi'); alias=default
"GET /ajax-search/?destination=Malaysia&people=1&days=5&budget=1500&currency=USD&visa_enabled=on HTTP/1.1" 200 2617
File /usr/local/lib/python3.9/site-packages/django/conf/locale/en/__init__.py first seen with mtime 1742333651.0
File /usr/local/lib/python3.9/site-packages/django/conf/locale/en/formats.py first seen with mtime 1742333651.0
(0.001) SELECT "django_session"."session_key", "django_session"."session_data", "django_session"."expire_date" FROM "django_session" WHERE ("django_session"."expire_date" > '2025-03-25T16:10:56.705862+00:00'::timestamptz AND "django_session"."session_key" = 't3u25nv8ifdkj0um0qal6s4s0zj2zawi') LIMIT 21; args=(datetime.datetime(2025, 3, 25, 16, 10, 56, 705862, tzinfo=datetime.timezone.utc), 't3u25nv8ifdkj0um0qal6s4s0zj2zawi'); alias=default
(0.001) SELECT "core_customuser"."id", "core_customuser"."password", "core_customuser"."last_login", "core_customuser"."is_superuser", "core_customuser"."username", "core_customuser"."first_name", "core_customuser"."last_name", "core_customuser"."email", "core_customuser"."is_staff", "core_customuser"."is_active", "core_customuser"."date_joined", "core_customuser"."country_id", "core_customuser"."budget", "core_customuser"."currency" FROM "core_customuser" WHERE "core_customuser"."id" = 2 LIMIT 21; args=(2,); alias=default
Exception while resolving variable 'login_form' in template 'details.html'.
Traceback (most recent call last):
  File "/usr/local/lib/python3.9/site-packages/django/template/base.py", line 862, in _resolve_lookup
    current = current[bit]
  File "/usr/local/lib/python3.9/site-packages/django/template/context.py", line 83, in __getitem__
    raise KeyError(key)
KeyError: 'login_form'

During handling of the above exception, another exception occurred:

Traceback (most recent call last):
  File "/usr/local/lib/python3.9/site-packages/django/template/base.py", line 868, in _resolve_lookup
    if isinstance(current, BaseContext) and getattr(type(current), bit):
AttributeError: type object 'RequestContext' has no attribute 'login_form'

During handling of the above exception, another exception occurred:

Traceback (most recent call last):
  File "/usr/local/lib/python3.9/site-packages/django/template/base.py", line 876, in _resolve_lookup
    current = current[int(bit)]
ValueError: invalid literal for int() with base 10: 'login_form'

During handling of the above exception, another exception occurred:

Traceback (most recent call last):
  File "/usr/local/lib/python3.9/site-packages/django/template/base.py", line 881, in _resolve_lookup
    raise VariableDoesNotExist("Failed lookup for key "
django.template.base.VariableDoesNotExist: Failed lookup for key [login_form] in [{'True': True, 'False': False, 'None': None}, {'csrf_token': <SimpleLazyObject: <function csrf.<locals>._get_val at 0x7fbda2d43790>>, 'request': <WSGIRequest: GET '/destination/kuala-lumpur/'>, 'user': <SimpleLazyObject: <CustomUser: user>>, 'perms': PermWrapper(<SimpleLazyObject: <CustomUser: user>>), 'messages': <FallbackStorage: request=<WSGIRequest: GET '/destination/kuala-lumpur/'>>, 'DEFAULT_MESSAGE_LEVELS': {'DEBUG': 10, 'INFO': 20, 'SUCCESS': 25, 'WARNING': 30, 'ERROR': 40}}, {}, {'destination': {'place_name': 'Kuala Lumpur', 'destination': 'Malaysia', 'days': 5, 'pax': 1, 'budget': '1500', 'currency': 'USD', 'destination_currency': 'USD', 'cost_in_destination_currency': 115.0, 'converted_cost': 115.0, 'cost_text': '115.0 USD', 'image_url': 'https://images.unsplash.com/photo-1477064996809-dae46985eee7?crop=entropy&cs=tinysrgb&fit=max&fm=jpg&ixid=M3w3MjUyMzB8MHwxfHJhbmRvbXx8fHx8fHx8fDE3NDI5MTkwMzN8&ixlib=rb-4.0.3&q=80&w=1080', 'description': 'Explore Kuala Lumpur, part of Malaysia', 'detail_url': '/destination/kuala-lumpur/', 'hotels': [], 'events': [], 'transport_cost': {'low_budget': 15.0, 'mid_range': 40.0, 'luxury': 150.0}, 'food_cost': {'low_budget': 25.0, 'mid_range': 75.0, 'luxury': 300.0}, 'short_visa': 'E-Visa', 'visa_text': {'short_visa': 'E-Visa', 'full_visa_text': "E-Visa\n\nAs a Russian citizen, you can apply for an e-Visa to visit Malaysia. There's no need to go in person to a consulate or embassy. It can be done from the comfort of your home or office in just a few minutes.\n\nTo be eligible for an e-Visa, you must have a valid passport for at least 6 months from the intended date of entry into Malaysia, a recent passport-size photo, proof of sufficient funds for the duration of your stay in Malaysia, confirmed return flight tickets, and accommodation information in Malaysia. \n\nThe e-Visa allows you to stay in Malaysia for 30 days, and it is a single entry visa. This visa is valid for three months from the date of issuance. You must apply for it at least 2 weeks prior to your planned trip. \n\nVisit the official Malaysia Immigration e-Visa Application website to start the application. Upon approval, it's recommended to print a copy of the e-Visa and bring it with you when traveling. \n\nAlways check the latest information, as visa policies might have changed. It's also a good idea to avoid visa overstays, as it may come with penalties or impact your ability to travel to Malaysia in the future."}}}, {}, {}]
Exception while resolving variable 'reg_form' in template 'details.html'.
Traceback (most recent call last):
  File "/usr/local/lib/python3.9/site-packages/django/template/base.py", line 862, in _resolve_lookup
    current = current[bit]
  File "/usr/local/lib/python3.9/site-packages/django/template/context.py", line 83, in __getitem__
    raise KeyError(key)
KeyError: 'reg_form'

During handling of the above exception, another exception occurred:

Traceback (most recent call last):
  File "/usr/local/lib/python3.9/site-packages/django/template/base.py", line 868, in _resolve_lookup
    if isinstance(current, BaseContext) and getattr(type(current), bit):
AttributeError: type object 'RequestContext' has no attribute 'reg_form'

During handling of the above exception, another exception occurred:

Traceback (most recent call last):
  File "/usr/local/lib/python3.9/site-packages/django/template/base.py", line 876, in _resolve_lookup
    current = current[int(bit)]
ValueError: invalid literal for int() with base 10: 'reg_form'

During handling of the above exception, another exception occurred:

Traceback (most recent call last):
  File "/usr/local/lib/python3.9/site-packages/django/template/base.py", line 881, in _resolve_lookup
    raise VariableDoesNotExist("Failed lookup for key "
django.template.base.VariableDoesNotExist: Failed lookup for key [reg_form] in [{'True': True, 'False': False, 'None': None}, {'csrf_token': <SimpleLazyObject: '9QuOyrGHeCeRMMmsTCSgipwewm9JghtGucOreABi7QiwDSTpSkoZ9YcSOCTX3O0F'>, 'request': <WSGIRequest: GET '/destination/kuala-lumpur/'>, 'user': <SimpleLazyObject: <CustomUser: user>>, 'perms': PermWrapper(<SimpleLazyObject: <CustomUser: user>>), 'messages': <FallbackStorage: request=<WSGIRequest: GET '/destination/kuala-lumpur/'>>, 'DEFAULT_MESSAGE_LEVELS': {'DEBUG': 10, 'INFO': 20, 'SUCCESS': 25, 'WARNING': 30, 'ERROR': 40}}, {}, {'destination': {'place_name': 'Kuala Lumpur', 'destination': 'Malaysia', 'days': 5, 'pax': 1, 'budget': '1500', 'currency': 'USD', 'destination_currency': 'USD', 'cost_in_destination_currency': 115.0, 'converted_cost': 115.0, 'cost_text': '115.0 USD', 'image_url': 'https://images.unsplash.com/photo-1477064996809-dae46985eee7?crop=entropy&cs=tinysrgb&fit=max&fm=jpg&ixid=M3w3MjUyMzB8MHwxfHJhbmRvbXx8fHx8fHx8fDE3NDI5MTkwMzN8&ixlib=rb-4.0.3&q=80&w=1080', 'description': 'Explore Kuala Lumpur, part of Malaysia', 'detail_url': '/destination/kuala-lumpur/', 'hotels': [], 'events': [], 'transport_cost': {'low_budget': 15.0, 'mid_range': 40.0, 'luxury': 150.0}, 'food_cost': {'low_budget': 25.0, 'mid_range': 75.0, 'luxury': 300.0}, 'short_visa': 'E-Visa', 'visa_text': {'short_visa': 'E-Visa', 'full_visa_text': "E-Visa\n\nAs a Russian citizen, you can apply for an e-Visa to visit Malaysia. There's no need to go in person to a consulate or embassy. It can be done from the comfort of your home or office in just a few minutes.\n\nTo be eligible for an e-Visa, you must have a valid passport for at least 6 months from the intended date of entry into Malaysia, a recent passport-size photo, proof of sufficient funds for the duration of your stay in Malaysia, confirmed return flight tickets, and accommodation information in Malaysia. \n\nThe e-Visa allows you to stay in Malaysia for 30 days, and it is a single entry visa. This visa is valid for three months from the date of issuance. You must apply for it at least 2 weeks prior to your planned trip. \n\nVisit the official Malaysia Immigration e-Visa Application website to start the application. Upon approval, it's recommended to print a copy of the e-Visa and bring it with you when traveling. \n\nAlways check the latest information, as visa policies might have changed. It's also a good idea to avoid visa overstays, as it may come with penalties or impact your ability to travel to Malaysia in the future."}}}, {}, {}]
Exception while resolving variable 'destination' in template 'details.html'.
Traceback (most recent call last):
  File "/usr/local/lib/python3.9/site-packages/django/utils/datastructures.py", line 83, in __getitem__
    list_ = super().__getitem__(key)
KeyError: 'destination'

During handling of the above exception, another exception occurred:

Traceback (most recent call last):
  File "/usr/local/lib/python3.9/site-packages/django/template/base.py", line 862, in _resolve_lookup
    current = current[bit]
  File "/usr/local/lib/python3.9/site-packages/django/utils/datastructures.py", line 85, in __getitem__
    raise MultiValueDictKeyError(key)
django.utils.datastructures.MultiValueDictKeyError: 'destination'

During handling of the above exception, another exception occurred:

Traceback (most recent call last):
  File "/usr/local/lib/python3.9/site-packages/django/template/base.py", line 870, in _resolve_lookup
    current = getattr(current, bit)
AttributeError: 'QueryDict' object has no attribute 'destination'

During handling of the above exception, another exception occurred:

Traceback (most recent call last):
  File "/usr/local/lib/python3.9/site-packages/django/template/base.py", line 876, in _resolve_lookup
    current = current[int(bit)]
ValueError: invalid literal for int() with base 10: 'destination'

During handling of the above exception, another exception occurred:

Traceback (most recent call last):
  File "/usr/local/lib/python3.9/site-packages/django/template/base.py", line 881, in _resolve_lookup
    raise VariableDoesNotExist("Failed lookup for key "
django.template.base.VariableDoesNotExist: Failed lookup for key [destination] in <QueryDict: {}>
Exception while resolving variable 'people' in template 'details.html'.
Traceback (most recent call last):
  File "/usr/local/lib/python3.9/site-packages/django/utils/datastructures.py", line 83, in __getitem__
    list_ = super().__getitem__(key)
KeyError: 'people'

During handling of the above exception, another exception occurred:

Traceback (most recent call last):
  File "/usr/local/lib/python3.9/site-packages/django/template/base.py", line 862, in _resolve_lookup
    current = current[bit]
  File "/usr/local/lib/python3.9/site-packages/django/utils/datastructures.py", line 85, in __getitem__
    raise MultiValueDictKeyError(key)
django.utils.datastructures.MultiValueDictKeyError: 'people'

During handling of the above exception, another exception occurred:

Traceback (most recent call last):
  File "/usr/local/lib/python3.9/site-packages/django/template/base.py", line 870, in _resolve_lookup
    current = getattr(current, bit)
AttributeError: 'QueryDict' object has no attribute 'people'

During handling of the above exception, another exception occurred:

Traceback (most recent call last):
  File "/usr/local/lib/python3.9/site-packages/django/template/base.py", line 876, in _resolve_lookup
    current = current[int(bit)]
ValueError: invalid literal for int() with base 10: 'people'

During handling of the above exception, another exception occurred:

Traceback (most recent call last):
  File "/usr/local/lib/python3.9/site-packages/django/template/base.py", line 881, in _resolve_lookup
    raise VariableDoesNotExist("Failed lookup for key "
django.template.base.VariableDoesNotExist: Failed lookup for key [people] in <QueryDict: {}>
Exception while resolving variable 'days' in template 'details.html'.
Traceback (most recent call last):
  File "/usr/local/lib/python3.9/site-packages/django/utils/datastructures.py", line 83, in __getitem__
    list_ = super().__getitem__(key)
KeyError: 'days'

During handling of the above exception, another exception occurred:

Traceback (most recent call last):
  File "/usr/local/lib/python3.9/site-packages/django/template/base.py", line 862, in _resolve_lookup
    current = current[bit]
  File "/usr/local/lib/python3.9/site-packages/django/utils/datastructures.py", line 85, in __getitem__
    raise MultiValueDictKeyError(key)
django.utils.datastructures.MultiValueDictKeyError: 'days'

During handling of the above exception, another exception occurred:

Traceback (most recent call last):
  File "/usr/local/lib/python3.9/site-packages/django/template/base.py", line 870, in _resolve_lookup
    current = getattr(current, bit)
AttributeError: 'QueryDict' object has no attribute 'days'

During handling of the above exception, another exception occurred:

Traceback (most recent call last):
  File "/usr/local/lib/python3.9/site-packages/django/template/base.py", line 876, in _resolve_lookup
    current = current[int(bit)]
ValueError: invalid literal for int() with base 10: 'days'

During handling of the above exception, another exception occurred:

Traceback (most recent call last):
  File "/usr/local/lib/python3.9/site-packages/django/template/base.py", line 881, in _resolve_lookup
    raise VariableDoesNotExist("Failed lookup for key "
django.template.base.VariableDoesNotExist: Failed lookup for key [days] in <QueryDict: {}>
Exception while resolving variable 'budget' in template 'details.html'.
Traceback (most recent call last):
  File "/usr/local/lib/python3.9/site-packages/django/utils/datastructures.py", line 83, in __getitem__
    list_ = super().__getitem__(key)
KeyError: 'budget'

During handling of the above exception, another exception occurred:

Traceback (most recent call last):
  File "/usr/local/lib/python3.9/site-packages/django/template/base.py", line 862, in _resolve_lookup
    current = current[bit]
  File "/usr/local/lib/python3.9/site-packages/django/utils/datastructures.py", line 85, in __getitem__
    raise MultiValueDictKeyError(key)
django.utils.datastructures.MultiValueDictKeyError: 'budget'

During handling of the above exception, another exception occurred:

Traceback (most recent call last):
  File "/usr/local/lib/python3.9/site-packages/django/template/base.py", line 870, in _resolve_lookup
    current = getattr(current, bit)
AttributeError: 'QueryDict' object has no attribute 'budget'

During handling of the above exception, another exception occurred:

Traceback (most recent call last):
  File "/usr/local/lib/python3.9/site-packages/django/template/base.py", line 876, in _resolve_lookup
    current = current[int(bit)]
ValueError: invalid literal for int() with base 10: 'budget'

During handling of the above exception, another exception occurred:

Traceback (most recent call last):
  File "/usr/local/lib/python3.9/site-packages/django/template/base.py", line 881, in _resolve_lookup
    raise VariableDoesNotExist("Failed lookup for key "
django.template.base.VariableDoesNotExist: Failed lookup for key [budget] in <QueryDict: {}>
Exception while resolving variable 'currency' in template 'details.html'.
Traceback (most recent call last):
  File "/usr/local/lib/python3.9/site-packages/django/utils/datastructures.py", line 83, in __getitem__
    list_ = super().__getitem__(key)
KeyError: 'currency'

During handling of the above exception, another exception occurred:

Traceback (most recent call last):
  File "/usr/local/lib/python3.9/site-packages/django/template/base.py", line 862, in _resolve_lookup
    current = current[bit]
  File "/usr/local/lib/python3.9/site-packages/django/utils/datastructures.py", line 85, in __getitem__
    raise MultiValueDictKeyError(key)
django.utils.datastructures.MultiValueDictKeyError: 'currency'

During handling of the above exception, another exception occurred:

Traceback (most recent call last):
  File "/usr/local/lib/python3.9/site-packages/django/template/base.py", line 870, in _resolve_lookup
    current = getattr(current, bit)
AttributeError: 'QueryDict' object has no attribute 'currency'

During handling of the above exception, another exception occurred:

Traceback (most recent call last):
  File "/usr/local/lib/python3.9/site-packages/django/template/base.py", line 876, in _resolve_lookup
    current = current[int(bit)]
ValueError: invalid literal for int() with base 10: 'currency'

During handling of the above exception, another exception occurred:

Traceback (most recent call last):
  File "/usr/local/lib/python3.9/site-packages/django/template/base.py", line 881, in _resolve_lookup
    raise VariableDoesNotExist("Failed lookup for key "
django.template.base.VariableDoesNotExist: Failed lookup for key [currency] in <QueryDict: {}>
(0.001) SELECT "core_country"."id", "core_country"."country_name", "core_country"."country_code", "core_country"."currency_code", "core_country"."currency_name", "core_country"."visa_requirement", "core_country"."average_travel_cost", "core_country"."description", "core_country"."image_url" FROM "core_country" WHERE "core_country"."id" = 193 LIMIT 21; args=(193,); alias=default
Exception while resolving variable 'visa_enabled' in template 'details.html'.
Traceback (most recent call last):
  File "/usr/local/lib/python3.9/site-packages/django/utils/datastructures.py", line 83, in __getitem__
    list_ = super().__getitem__(key)
KeyError: 'visa_enabled'

During handling of the above exception, another exception occurred:

Traceback (most recent call last):
  File "/usr/local/lib/python3.9/site-packages/django/template/base.py", line 862, in _resolve_lookup
    current = current[bit]
  File "/usr/local/lib/python3.9/site-packages/django/utils/datastructures.py", line 85, in __getitem__
    raise MultiValueDictKeyError(key)
django.utils.datastructures.MultiValueDictKeyError: 'visa_enabled'

During handling of the above exception, another exception occurred:

Traceback (most recent call last):
  File "/usr/local/lib/python3.9/site-packages/django/template/base.py", line 870, in _resolve_lookup
    current = getattr(current, bit)
AttributeError: 'QueryDict' object has no attribute 'visa_enabled'

During handling of the above exception, another exception occurred:

Traceback (most recent call last):
  File "/usr/local/lib/python3.9/site-packages/django/template/base.py", line 876, in _resolve_lookup
    current = current[int(bit)]
ValueError: invalid literal for int() with base 10: 'visa_enabled'

During handling of the above exception, another exception occurred:

Traceback (most recent call last):
  File "/usr/local/lib/python3.9/site-packages/django/template/base.py", line 881, in _resolve_lookup
    raise VariableDoesNotExist("Failed lookup for key "
django.template.base.VariableDoesNotExist: Failed lookup for key [visa_enabled] in <QueryDict: {}>
Exception while resolving variable 'get_error_message' in template 'details.html'.
Traceback (most recent call last):
  File "/usr/local/lib/python3.9/site-packages/django/template/base.py", line 862, in _resolve_lookup
    current = current[bit]
TypeError: 'FallbackStorage' object is not subscriptable

During handling of the above exception, another exception occurred:

Traceback (most recent call last):
  File "/usr/local/lib/python3.9/site-packages/django/template/base.py", line 870, in _resolve_lookup
    current = getattr(current, bit)
AttributeError: 'FallbackStorage' object has no attribute 'get_error_message'

During handling of the above exception, another exception occurred:

Traceback (most recent call last):
  File "/usr/local/lib/python3.9/site-packages/django/template/base.py", line 876, in _resolve_lookup
    current = current[int(bit)]
ValueError: invalid literal for int() with base 10: 'get_error_message'

During handling of the above exception, another exception occurred:

Traceback (most recent call last):
  File "/usr/local/lib/python3.9/site-packages/django/template/base.py", line 881, in _resolve_lookup
    raise VariableDoesNotExist("Failed lookup for key "
django.template.base.VariableDoesNotExist: Failed lookup for key [get_error_message] in <FallbackStorage: request=<WSGIRequest: GET '/destination/kuala-lumpur/'>>
Exception while resolving variable 'searched' in template 'details.html'.
Traceback (most recent call last):
  File "/usr/local/lib/python3.9/site-packages/django/template/base.py", line 862, in _resolve_lookup
    current = current[bit]
  File "/usr/local/lib/python3.9/site-packages/django/template/context.py", line 83, in __getitem__
    raise KeyError(key)
KeyError: 'searched'

During handling of the above exception, another exception occurred:

Traceback (most recent call last):
  File "/usr/local/lib/python3.9/site-packages/django/template/base.py", line 868, in _resolve_lookup
    if isinstance(current, BaseContext) and getattr(type(current), bit):
AttributeError: type object 'RequestContext' has no attribute 'searched'

During handling of the above exception, another exception occurred:

Traceback (most recent call last):
  File "/usr/local/lib/python3.9/site-packages/django/template/base.py", line 876, in _resolve_lookup
    current = current[int(bit)]
ValueError: invalid literal for int() with base 10: 'searched'

During handling of the above exception, another exception occurred:

Traceback (most recent call last):
  File "/usr/local/lib/python3.9/site-packages/django/template/base.py", line 881, in _resolve_lookup
    raise VariableDoesNotExist("Failed lookup for key "
django.template.base.VariableDoesNotExist: Failed lookup for key [searched] in [{'True': True, 'False': False, 'None': None}, {'csrf_token': <SimpleLazyObject: '9QuOyrGHeCeRMMmsTCSgipwewm9JghtGucOreABi7QiwDSTpSkoZ9YcSOCTX3O0F'>, 'request': <WSGIRequest: GET '/destination/kuala-lumpur/'>, 'user': <SimpleLazyObject: <CustomUser: user>>, 'perms': PermWrapper(<SimpleLazyObject: <CustomUser: user>>), 'messages': <FallbackStorage: request=<WSGIRequest: GET '/destination/kuala-lumpur/'>>, 'DEFAULT_MESSAGE_LEVELS': {'DEBUG': 10, 'INFO': 20, 'SUCCESS': 25, 'WARNING': 30, 'ERROR': 40}}, {}, {'destination': {'place_name': 'Kuala Lumpur', 'destination': 'Malaysia', 'days': 5, 'pax': 1, 'budget': '1500', 'currency': 'USD', 'destination_currency': 'USD', 'cost_in_destination_currency': 115.0, 'converted_cost': 115.0, 'cost_text': '115.0 USD', 'image_url': 'https://images.unsplash.com/photo-1477064996809-dae46985eee7?crop=entropy&cs=tinysrgb&fit=max&fm=jpg&ixid=M3w3MjUyMzB8MHwxfHJhbmRvbXx8fHx8fHx8fDE3NDI5MTkwMzN8&ixlib=rb-4.0.3&q=80&w=1080', 'description': 'Explore Kuala Lumpur, part of Malaysia', 'detail_url': '/destination/kuala-lumpur/', 'hotels': [], 'events': [], 'transport_cost': {'low_budget': 15.0, 'mid_range': 40.0, 'luxury': 150.0}, 'food_cost': {'low_budget': 25.0, 'mid_range': 75.0, 'luxury': 300.0}, 'short_visa': 'E-Visa', 'visa_text': {'short_visa': 'E-Visa', 'full_visa_text': "E-Visa\n\nAs a Russian citizen, you can apply for an e-Visa to visit Malaysia. There's no need to go in person to a consulate or embassy. It can be done from the comfort of your home or office in just a few minutes.\n\nTo be eligible for an e-Visa, you must have a valid passport for at least 6 months from the intended date of entry into Malaysia, a recent passport-size photo, proof of sufficient funds for the duration of your stay in Malaysia, confirmed return flight tickets, and accommodation information in Malaysia. \n\nThe e-Visa allows you to stay in Malaysia for 30 days, and it is a single entry visa. This visa is valid for three months from the date of issuance. You must apply for it at least 2 weeks prior to your planned trip. \n\nVisit the official Malaysia Immigration e-Visa Application website to start the application. Upon approval, it's recommended to print a copy of the e-Visa and bring it with you when traveling. \n\nAlways check the latest information, as visa policies might have changed. It's also a good idea to avoid visa overstays, as it may come with penalties or impact your ability to travel to Malaysia in the future."}}}, {}]
"GET /destination/kuala-lumpur/ HTTP/1.1" 200 20503
Not Found: /destination/assets/images/favicon.svg
"GET /destination/assets/images/favicon.svg HTTP/1.1" 404 3409
Not Found: /serviceworker.js
"GET /serviceworker.js HTTP/1.1" 404 3346
Not Found: /serviceworker.js
"GET /serviceworker.js HTTP/1.1" 404 3346
(0.001) SELECT "django_session"."session_key", "django_session"."session_data", "django_session"."expire_date" FROM "django_session" WHERE ("django_session"."expire_date" > '2025-03-25T16:12:39.951206+00:00'::timestamptz AND "django_session"."session_key" = 't3u25nv8ifdkj0um0qal6s4s0zj2zawi') LIMIT 21; args=(datetime.datetime(2025, 3, 25, 16, 12, 39, 951206, tzinfo=datetime.timezone.utc), 't3u25nv8ifdkj0um0qal6s4s0zj2zawi'); alias=default
(0.000) SELECT "core_customuser"."id", "core_customuser"."password", "core_customuser"."last_login", "core_customuser"."is_superuser", "core_customuser"."username", "core_customuser"."first_name", "core_customuser"."last_name", "core_customuser"."email", "core_customuser"."is_staff", "core_customuser"."is_active", "core_customuser"."date_joined", "core_customuser"."country_id", "core_customuser"."budget", "core_customuser"."currency" FROM "core_customuser" WHERE "core_customuser"."id" = 2 LIMIT 21; args=(2,); alias=default
Exception while resolving variable 'login_form' in template 'utils/profile.html'.
Traceback (most recent call last):
  File "/usr/local/lib/python3.9/site-packages/django/template/base.py", line 862, in _resolve_lookup
    current = current[bit]
  File "/usr/local/lib/python3.9/site-packages/django/template/context.py", line 83, in __getitem__
    raise KeyError(key)
KeyError: 'login_form'

During handling of the above exception, another exception occurred:

Traceback (most recent call last):
  File "/usr/local/lib/python3.9/site-packages/django/template/base.py", line 868, in _resolve_lookup
    if isinstance(current, BaseContext) and getattr(type(current), bit):
AttributeError: type object 'RequestContext' has no attribute 'login_form'

During handling of the above exception, another exception occurred:

Traceback (most recent call last):
  File "/usr/local/lib/python3.9/site-packages/django/template/base.py", line 876, in _resolve_lookup
    current = current[int(bit)]
ValueError: invalid literal for int() with base 10: 'login_form'

During handling of the above exception, another exception occurred:

Traceback (most recent call last):
  File "/usr/local/lib/python3.9/site-packages/django/template/base.py", line 881, in _resolve_lookup
    raise VariableDoesNotExist("Failed lookup for key "
django.template.base.VariableDoesNotExist: Failed lookup for key [login_form] in [{'True': True, 'False': False, 'None': None}, {'csrf_token': <SimpleLazyObject: <function csrf.<locals>._get_val at 0x7fbda01de3a0>>, 'request': <WSGIRequest: GET '/profile/'>, 'user': <SimpleLazyObject: <CustomUser: user>>, 'perms': PermWrapper(<SimpleLazyObject: <CustomUser: user>>), 'messages': <FallbackStorage: request=<WSGIRequest: GET '/profile/'>>, 'DEFAULT_MESSAGE_LEVELS': {'DEBUG': 10, 'INFO': 20, 'SUCCESS': 25, 'WARNING': 30, 'ERROR': 40}}, {}, {}, {}]
Exception while resolving variable 'reg_form' in template 'utils/profile.html'.
Traceback (most recent call last):
  File "/usr/local/lib/python3.9/site-packages/django/template/base.py", line 862, in _resolve_lookup
    current = current[bit]
  File "/usr/local/lib/python3.9/site-packages/django/template/context.py", line 83, in __getitem__
    raise KeyError(key)
KeyError: 'reg_form'

During handling of the above exception, another exception occurred:

Traceback (most recent call last):
  File "/usr/local/lib/python3.9/site-packages/django/template/base.py", line 868, in _resolve_lookup
    if isinstance(current, BaseContext) and getattr(type(current), bit):
AttributeError: type object 'RequestContext' has no attribute 'reg_form'

During handling of the above exception, another exception occurred:

Traceback (most recent call last):
  File "/usr/local/lib/python3.9/site-packages/django/template/base.py", line 876, in _resolve_lookup
    current = current[int(bit)]
ValueError: invalid literal for int() with base 10: 'reg_form'

During handling of the above exception, another exception occurred:

Traceback (most recent call last):
  File "/usr/local/lib/python3.9/site-packages/django/template/base.py", line 881, in _resolve_lookup
    raise VariableDoesNotExist("Failed lookup for key "
django.template.base.VariableDoesNotExist: Failed lookup for key [reg_form] in [{'True': True, 'False': False, 'None': None}, {'csrf_token': <SimpleLazyObject: 'PJaOSb5DVs6tlqZrXLODIpo9Rsq8vz9Ma5uryk0eOGa8cwwoWtkmzY4N9Iami6GL'>, 'request': <WSGIRequest: GET '/profile/'>, 'user': <SimpleLazyObject: <CustomUser: user>>, 'perms': PermWrapper(<SimpleLazyObject: <CustomUser: user>>), 'messages': <FallbackStorage: request=<WSGIRequest: GET '/profile/'>>, 'DEFAULT_MESSAGE_LEVELS': {'DEBUG': 10, 'INFO': 20, 'SUCCESS': 25, 'WARNING': 30, 'ERROR': 40}}, {}, {}, {}]
(0.001) SELECT "core_country"."id", "core_country"."country_name", "core_country"."country_code", "core_country"."currency_code", "core_country"."currency_name", "core_country"."visa_requirement", "core_country"."average_travel_cost", "core_country"."description", "core_country"."image_url" FROM "core_country" WHERE "core_country"."id" = 193 LIMIT 21; args=(193,); alias=default
"GET /profile/ HTTP/1.1" 200 15385
Not Found: /serviceworker.js
"GET /serviceworker.js HTTP/1.1" 404 3346
Not Found: /serviceworker.js
"GET /serviceworker.js HTTP/1.1" 404 3346
Not Found: /serviceworker.js
"GET /serviceworker.js HTTP/1.1" 404 3346
